2025-03-28 20:54:41,691 - INFO - Start polling
2025-03-28 20:54:42,103 - INFO - Run polling for bot @Testo1113_Bot id=7597499330 - 'Testo123'
2025-03-28 20:55:00,661 - INFO - Update id=821253725 is handled. Duration 436 ms by bot id=7597499330
2025-03-28 20:55:02,931 - INFO - Update id=821253726 is handled. Duration 202 ms by bot id=7597499330
2025-03-28 20:55:12,271 - INFO - Connecting to 149.154.167.51:443/TcpFull...
2025-03-28 20:55:13,692 - INFO - Connection to 149.154.167.51:443/TcpFull complete!
2025-03-28 20:55:14,673 - INFO - Update id=821253727 is handled. Duration 2438 ms by bot id=7597499330
2025-03-28 20:55:22,459 - INFO - Update id=821253728 is handled. Duration 608 ms by bot id=7597499330
2025-03-28 20:55:32,639 - INFO - Update id=821253729 is handled. Duration 171 ms by bot id=7597499330
2025-03-28 20:55:34,879 - INFO - Update id=821253730 is handled. Duration 155 ms by bot id=7597499330
2025-03-28 20:55:36,830 - INFO - Update id=821253731 is handled. Duration 312 ms by bot id=7597499330
2025-03-28 20:55:41,657 - INFO - Update id=821253732 is handled. Duration 172 ms by bot id=7597499330
2025-03-28 20:55:43,423 - INFO - Update id=821253733 is not handled. Duration 156 ms by bot id=7597499330
2025-03-28 20:55:43,423 - ERROR - Cause exception while process update id=821253733 by bot id=7597499330
TypeError: handle_errors() missing 1 required positional argument: 'exception'
Traceback (most recent call last):
  File "C:\Users\AORUS\Documents\GitHub\Bot7k\venv\lib\site-packages\aiogram\dispatcher\middlewares\error.py", line 25, in __call__
    return await handler(event, data)
  File "C:\Users\AORUS\Documents\GitHub\Bot7k\venv\lib\site-packages\aiogram\dispatcher\middlewares\user_context.py", line 27, in __call__
    return await handler(event, data)
  File "C:\Users\AORUS\Documents\GitHub\Bot7k\venv\lib\site-packages\aiogram\fsm\middleware.py", line 39, in __call__
    return await handler(event, data)
  File "C:\Users\AORUS\Documents\GitHub\Bot7k\venv\lib\site-packages\aiogram\dispatcher\event\telegram.py", line 120, in trigger
    return await wrapped_inner(event, kwargs)
  File "C:\Users\AORUS\Documents\GitHub\Bot7k\venv\lib\site-packages\aiogram\dispatcher\event\handler.py", line 42, in call
    return await wrapped()
  File "C:\Users\AORUS\Documents\GitHub\Bot7k\venv\lib\site-packages\aiogram\dispatcher\dispatcher.py", line 275, in _listen_update
    return await self.propagate_event(update_type=update_type, event=event, **kwargs)
  File "C:\Users\AORUS\Documents\GitHub\Bot7k\venv\lib\site-packages\aiogram\dispatcher\router.py", line 116, in propagate_event
    return await observer.wrap_outer_middleware(_wrapped, event=event, data=kwargs)
  File "C:\Users\AORUS\Documents\GitHub\Bot7k\venv\lib\site-packages\aiogram\dispatcher\router.py", line 111, in _wrapped
    return await self._propagate_event(
  File "C:\Users\AORUS\Documents\GitHub\Bot7k\venv\lib\site-packages\aiogram\dispatcher\router.py", line 136, in _propagate_event
    response = await observer.trigger(event, **kwargs)
  File "C:\Users\AORUS\Documents\GitHub\Bot7k\venv\lib\site-packages\aiogram\dispatcher\event\telegram.py", line 120, in trigger
    return await wrapped_inner(event, kwargs)
  File "C:\Users\AORUS\Documents\GitHub\Bot7k\venv\lib\site-packages\aiogram\dispatcher\event\handler.py", line 42, in call
    return await wrapped()
  File "C:\Users\AORUS\Documents\GitHub\Bot7k\bot.py", line 829, in process_message_selection
    await client.disconnect()  # Добавьте отключение
UnboundLocalError: local variable 'client' referenced before assignment

During handling of the above exception, another exception occurred:

Traceback (most recent call last):
  File "C:\Users\AORUS\Documents\GitHub\Bot7k\venv\lib\site-packages\aiogram\dispatcher\dispatcher.py", line 308, in _process_update
    response = await self.feed_update(bot, update, **kwargs)
  File "C:\Users\AORUS\Documents\GitHub\Bot7k\venv\lib\site-packages\aiogram\dispatcher\dispatcher.py", line 157, in feed_update
    response = await self.update.wrap_outer_middleware(
  File "C:\Users\AORUS\Documents\GitHub\Bot7k\venv\lib\site-packages\aiogram\dispatcher\middlewares\error.py", line 29, in __call__
    response = await self.router.propagate_event(
  File "C:\Users\AORUS\Documents\GitHub\Bot7k\venv\lib\site-packages\aiogram\dispatcher\router.py", line 116, in propagate_event
    return await observer.wrap_outer_middleware(_wrapped, event=event, data=kwargs)
  File "C:\Users\AORUS\Documents\GitHub\Bot7k\venv\lib\site-packages\aiogram\dispatcher\router.py", line 111, in _wrapped
    return await self._propagate_event(
  File "C:\Users\AORUS\Documents\GitHub\Bot7k\venv\lib\site-packages\aiogram\dispatcher\router.py", line 136, in _propagate_event
    response = await observer.trigger(event, **kwargs)
  File "C:\Users\AORUS\Documents\GitHub\Bot7k\venv\lib\site-packages\aiogram\dispatcher\event\telegram.py", line 120, in trigger
    return await wrapped_inner(event, kwargs)
  File "C:\Users\AORUS\Documents\GitHub\Bot7k\venv\lib\site-packages\aiogram\dispatcher\event\handler.py", line 42, in call
    return await wrapped()
TypeError: handle_errors() missing 1 required positional argument: 'exception'
2025-03-28 20:55:47,828 - INFO - Update id=821253734 is not handled. Duration 0 ms by bot id=7597499330
2025-03-28 20:55:49,883 - INFO - Update id=821253735 is not handled. Duration 0 ms by bot id=7597499330
2025-03-28 20:55:53,238 - INFO - Update id=821253736 is not handled. Duration 0 ms by bot id=7597499330
2025-03-28 20:55:58,773 - INFO - Update id=821253737 is handled. Duration 359 ms by bot id=7597499330
2025-03-28 20:56:00,656 - INFO - Update id=821253738 is not handled. Duration 0 ms by bot id=7597499330
2025-03-28 20:56:03,626 - INFO - Update id=821253739 is not handled. Duration 0 ms by bot id=7597499330
2025-03-28 20:56:04,419 - INFO - Update id=821253740 is not handled. Duration 16 ms by bot id=7597499330
2025-03-28 20:56:04,928 - INFO - Update id=821253741 is not handled. Duration 0 ms by bot id=7597499330
2025-03-28 20:56:05,231 - INFO - Update id=821253742 is not handled. Duration 14 ms by bot id=7597499330
2025-03-28 20:56:05,406 - INFO - Update id=821253743 is not handled. Duration 15 ms by bot id=7597499330
2025-03-28 20:56:05,639 - INFO - Update id=821253744 is not handled. Duration 16 ms by bot id=7597499330
2025-03-28 20:56:09,789 - INFO - Update id=821253745 is handled. Duration 202 ms by bot id=7597499330
2025-03-28 20:56:11,968 - INFO - Update id=821253746 is handled. Duration 203 ms by bot id=7597499330
2025-03-28 20:56:14,193 - INFO - Update id=821253747 is handled. Duration 297 ms by bot id=7597499330
2025-03-28 20:56:18,353 - INFO - Update id=821253748 is handled. Duration 156 ms by bot id=7597499330
2025-03-28 20:56:19,889 - INFO - Update id=821253749 is handled. Duration 157 ms by bot id=7597499330
2025-03-28 20:56:21,459 - INFO - Update id=821253750 is handled. Duration 219 ms by bot id=7597499330
2025-03-28 20:56:24,900 - INFO - Update id=821253751 is handled. Duration 157 ms by bot id=7597499330
2025-03-28 20:56:26,480 - INFO - Update id=821253752 is handled. Duration 235 ms by bot id=7597499330
2025-03-28 20:56:28,386 - INFO - Update id=821253753 is handled. Duration 687 ms by bot id=7597499330
2025-03-28 20:57:03,018 - INFO - Update id=821253754 is handled. Duration 437 ms by bot id=7597499330
2025-03-28 20:57:06,325 - INFO - Update id=821253755 is not handled. Duration 172 ms by bot id=7597499330
2025-03-28 20:57:06,325 - ERROR - Cause exception while process update id=821253755 by bot id=7597499330
TypeError: handle_errors() missing 1 required positional argument: 'exception'
Traceback (most recent call last):
  File "C:\Users\AORUS\Documents\GitHub\Bot7k\venv\lib\site-packages\aiogram\dispatcher\middlewares\error.py", line 25, in __call__
    return await handler(event, data)
  File "C:\Users\AORUS\Documents\GitHub\Bot7k\venv\lib\site-packages\aiogram\dispatcher\middlewares\user_context.py", line 27, in __call__
    return await handler(event, data)
  File "C:\Users\AORUS\Documents\GitHub\Bot7k\venv\lib\site-packages\aiogram\fsm\middleware.py", line 39, in __call__
    return await handler(event, data)
  File "C:\Users\AORUS\Documents\GitHub\Bot7k\venv\lib\site-packages\aiogram\dispatcher\event\telegram.py", line 120, in trigger
    return await wrapped_inner(event, kwargs)
  File "C:\Users\AORUS\Documents\GitHub\Bot7k\venv\lib\site-packages\aiogram\dispatcher\event\handler.py", line 42, in call
    return await wrapped()
  File "C:\Users\AORUS\Documents\GitHub\Bot7k\venv\lib\site-packages\aiogram\dispatcher\dispatcher.py", line 275, in _listen_update
    return await self.propagate_event(update_type=update_type, event=event, **kwargs)
  File "C:\Users\AORUS\Documents\GitHub\Bot7k\venv\lib\site-packages\aiogram\dispatcher\router.py", line 116, in propagate_event
    return await observer.wrap_outer_middleware(_wrapped, event=event, data=kwargs)
  File "C:\Users\AORUS\Documents\GitHub\Bot7k\venv\lib\site-packages\aiogram\dispatcher\router.py", line 111, in _wrapped
    return await self._propagate_event(
  File "C:\Users\AORUS\Documents\GitHub\Bot7k\venv\lib\site-packages\aiogram\dispatcher\router.py", line 136, in _propagate_event
    response = await observer.trigger(event, **kwargs)
  File "C:\Users\AORUS\Documents\GitHub\Bot7k\venv\lib\site-packages\aiogram\dispatcher\event\telegram.py", line 120, in trigger
    return await wrapped_inner(event, kwargs)
  File "C:\Users\AORUS\Documents\GitHub\Bot7k\venv\lib\site-packages\aiogram\dispatcher\event\handler.py", line 42, in call
    return await wrapped()
  File "C:\Users\AORUS\Documents\GitHub\Bot7k\bot.py", line 829, in process_message_selection
    await client.disconnect()  # Добавьте отключение
UnboundLocalError: local variable 'client' referenced before assignment

During handling of the above exception, another exception occurred:

Traceback (most recent call last):
  File "C:\Users\AORUS\Documents\GitHub\Bot7k\venv\lib\site-packages\aiogram\dispatcher\dispatcher.py", line 308, in _process_update
    response = await self.feed_update(bot, update, **kwargs)
  File "C:\Users\AORUS\Documents\GitHub\Bot7k\venv\lib\site-packages\aiogram\dispatcher\dispatcher.py", line 157, in feed_update
    response = await self.update.wrap_outer_middleware(
  File "C:\Users\AORUS\Documents\GitHub\Bot7k\venv\lib\site-packages\aiogram\dispatcher\middlewares\error.py", line 29, in __call__
    response = await self.router.propagate_event(
  File "C:\Users\AORUS\Documents\GitHub\Bot7k\venv\lib\site-packages\aiogram\dispatcher\router.py", line 116, in propagate_event
    return await observer.wrap_outer_middleware(_wrapped, event=event, data=kwargs)
  File "C:\Users\AORUS\Documents\GitHub\Bot7k\venv\lib\site-packages\aiogram\dispatcher\router.py", line 111, in _wrapped
    return await self._propagate_event(
  File "C:\Users\AORUS\Documents\GitHub\Bot7k\venv\lib\site-packages\aiogram\dispatcher\router.py", line 136, in _propagate_event
    response = await observer.trigger(event, **kwargs)
  File "C:\Users\AORUS\Documents\GitHub\Bot7k\venv\lib\site-packages\aiogram\dispatcher\event\telegram.py", line 120, in trigger
    return await wrapped_inner(event, kwargs)
  File "C:\Users\AORUS\Documents\GitHub\Bot7k\venv\lib\site-packages\aiogram\dispatcher\event\handler.py", line 42, in call
    return await wrapped()
TypeError: handle_errors() missing 1 required positional argument: 'exception'
2025-03-28 21:07:18,583 - INFO - Polling stopped for bot @Testo1113_Bot id=7597499330 - 'Testo123'
2025-03-28 21:07:18,583 - INFO - Polling stopped
2025-03-28 21:07:18,585 - INFO - Бот остановлен пользователем
2025-03-28 21:07:20,929 - INFO - Connecting to 149.154.167.51:443/TcpFull...
2025-03-28 21:07:21,060 - INFO - Connection to 149.154.167.51:443/TcpFull complete!
2025-03-28 21:07:21,637 - INFO - Start polling
2025-03-28 21:07:22,181 - INFO - Run polling for bot @Testo1113_Bot id=7597499330 - 'Testo123'
2025-03-28 21:07:33,151 - INFO - Polling stopped for bot @Testo1113_Bot id=7597499330 - 'Testo123'
2025-03-28 21:07:33,151 - INFO - Polling stopped
2025-03-28 21:07:33,152 - INFO - Бот остановлен пользователем
2025-03-28 21:08:23,091 - INFO - Connecting to 149.154.167.51:443/TcpFull...
2025-03-28 21:08:23,222 - INFO - Connection to 149.154.167.51:443/TcpFull complete!
2025-03-28 21:08:24,049 - INFO - Start polling
2025-03-28 21:08:24,460 - INFO - Run polling for bot @Testo1113_Bot id=7597499330 - 'Testo123'
2025-03-28 21:08:45,952 - INFO - Update id=821253756 is handled. Duration 437 ms by bot id=7597499330
2025-03-28 21:08:53,470 - INFO - Update id=821253757 is handled. Duration 203 ms by bot id=7597499330
2025-03-28 21:08:55,596 - INFO - Update id=821253758 is handled. Duration 453 ms by bot id=7597499330
2025-03-28 21:09:15,778 - INFO - Update id=821253759 is not handled. Duration 15 ms by bot id=7597499330
2025-03-28 21:09:33,558 - INFO - Update id=821253760 is not handled. Duration 16 ms by bot id=7597499330
2025-03-28 21:09:39,417 - INFO - Update id=821253761 is handled. Duration 438 ms by bot id=7597499330
2025-03-28 21:09:42,611 - INFO - Connecting to 149.154.167.51:443/TcpFull...
2025-03-28 21:09:42,743 - INFO - Connection to 149.154.167.51:443/TcpFull complete!
2025-03-28 21:09:43,892 - INFO - Update id=821253762 is handled. Duration 1282 ms by bot id=7597499330
2025-03-28 21:09:56,949 - INFO - Update id=821253763 is not handled. Duration 15 ms by bot id=7597499330
2025-03-28 21:10:05,036 - INFO - Update id=821253764 is handled. Duration 561 ms by bot id=7597499330
2025-03-28 21:10:07,066 - INFO - Update id=821253765 is handled. Duration 172 ms by bot id=7597499330
2025-03-28 21:10:08,696 - INFO - Update id=821253766 is handled. Duration 313 ms by bot id=7597499330
2025-03-28 21:10:11,364 - INFO - Update id=821253767 is handled. Duration 170 ms by bot id=7597499330
2025-03-28 21:10:13,251 - INFO - Connecting to 149.154.167.51:443/TcpFull...
2025-03-28 21:10:13,381 - INFO - Connection to 149.154.167.51:443/TcpFull complete!
2025-03-28 21:10:19,082 - INFO - Update id=821253768 is handled. Duration 5844 ms by bot id=7597499330
2025-03-28 21:10:29,794 - ERROR - Task was destroyed but it is pending!
task: <Task pending name='Task-84' coro=<Connection._send_loop() running at C:\Users\AORUS\Documents\GitHub\Bot7k\venv\lib\site-packages\telethon\network\connection\connection.py:322> wait_for=<Future pending cb=[Task.task_wakeup()]>>
2025-03-28 21:10:29,794 - ERROR - Task was destroyed but it is pending!
task: <Task pending name='Task-85' coro=<Connection._recv_loop() running at C:\Users\AORUS\Documents\GitHub\Bot7k\venv\lib\site-packages\telethon\network\connection\connection.py:341> wait_for=<Future pending cb=[Task.task_wakeup()]>>
2025-03-28 21:10:29,794 - ERROR - Task was destroyed but it is pending!
task: <Task pending name='Task-86' coro=<MTProtoSender._send_loop() running at C:\Users\AORUS\Documents\GitHub\Bot7k\venv\lib\site-packages\telethon\network\mtprotosender.py:464> wait_for=<Future pending cb=[Task.task_wakeup()]>>
2025-03-28 21:10:29,794 - ERROR - Task was destroyed but it is pending!
task: <Task pending name='Task-87' coro=<MTProtoSender._recv_loop() running at C:\Users\AORUS\Documents\GitHub\Bot7k\venv\lib\site-packages\telethon\network\mtprotosender.py:507> wait_for=<Future pending cb=[Task.task_wakeup()]>>
2025-03-28 21:10:30,073 - INFO - Update id=821253769 is handled. Duration 469 ms by bot id=7597499330
2025-03-28 21:10:33,215 - INFO - Update id=821253770 is handled. Duration 438 ms by bot id=7597499330
2025-03-28 21:10:34,900 - INFO - Update id=821253771 is handled. Duration 516 ms by bot id=7597499330
2025-03-28 21:10:35,763 - INFO - Update id=821253772 is handled. Duration 484 ms by bot id=7597499330
2025-03-28 21:10:36,634 - INFO - Update id=821253773 is handled. Duration 421 ms by bot id=7597499330
2025-03-28 21:10:37,189 - INFO - Update id=821253774 is handled. Duration 391 ms by bot id=7597499330
2025-03-28 21:10:41,010 - INFO - Update id=821253775 is handled. Duration 311 ms by bot id=7597499330
2025-03-28 21:10:41,243 - INFO - Update id=821253776 is not handled. Duration 405 ms by bot id=7597499330
2025-03-28 21:10:41,243 - ERROR - Cause exception while process update id=821253776 by bot id=7597499330
TypeError: handle_errors() missing 1 required positional argument: 'exception'
Traceback (most recent call last):
  File "C:\Users\AORUS\Documents\GitHub\Bot7k\venv\lib\site-packages\aiogram\dispatcher\middlewares\error.py", line 25, in __call__
    return await handler(event, data)
  File "C:\Users\AORUS\Documents\GitHub\Bot7k\venv\lib\site-packages\aiogram\dispatcher\middlewares\user_context.py", line 27, in __call__
    return await handler(event, data)
  File "C:\Users\AORUS\Documents\GitHub\Bot7k\venv\lib\site-packages\aiogram\fsm\middleware.py", line 39, in __call__
    return await handler(event, data)
  File "C:\Users\AORUS\Documents\GitHub\Bot7k\venv\lib\site-packages\aiogram\dispatcher\event\telegram.py", line 120, in trigger
    return await wrapped_inner(event, kwargs)
  File "C:\Users\AORUS\Documents\GitHub\Bot7k\venv\lib\site-packages\aiogram\dispatcher\event\handler.py", line 42, in call
    return await wrapped()
  File "C:\Users\AORUS\Documents\GitHub\Bot7k\venv\lib\site-packages\aiogram\dispatcher\dispatcher.py", line 275, in _listen_update
    return await self.propagate_event(update_type=update_type, event=event, **kwargs)
  File "C:\Users\AORUS\Documents\GitHub\Bot7k\venv\lib\site-packages\aiogram\dispatcher\router.py", line 116, in propagate_event
    return await observer.wrap_outer_middleware(_wrapped, event=event, data=kwargs)
  File "C:\Users\AORUS\Documents\GitHub\Bot7k\venv\lib\site-packages\aiogram\dispatcher\router.py", line 111, in _wrapped
    return await self._propagate_event(
  File "C:\Users\AORUS\Documents\GitHub\Bot7k\venv\lib\site-packages\aiogram\dispatcher\router.py", line 136, in _propagate_event
    response = await observer.trigger(event, **kwargs)
  File "C:\Users\AORUS\Documents\GitHub\Bot7k\venv\lib\site-packages\aiogram\dispatcher\event\telegram.py", line 120, in trigger
    return await wrapped_inner(event, kwargs)
  File "C:\Users\AORUS\Documents\GitHub\Bot7k\venv\lib\site-packages\aiogram\dispatcher\event\handler.py", line 42, in call
    return await wrapped()
  File "C:\Users\AORUS\Documents\GitHub\Bot7k\bot.py", line 785, in handle_message_pagination
    await callback.message.edit_reply_markup(
  File "C:\Users\AORUS\Documents\GitHub\Bot7k\venv\lib\site-packages\aiogram\methods\base.py", line 84, in emit
    return await bot(self)
  File "C:\Users\AORUS\Documents\GitHub\Bot7k\venv\lib\site-packages\aiogram\client\bot.py", line 432, in __call__
    return await self.session(self, method, timeout=request_timeout)
  File "C:\Users\AORUS\Documents\GitHub\Bot7k\venv\lib\site-packages\aiogram\client\session\base.py", line 257, in __call__
    return cast(TelegramType, await middleware(bot, method))
  File "C:\Users\AORUS\Documents\GitHub\Bot7k\venv\lib\site-packages\aiogram\client\session\aiohttp.py", line 175, in make_request
    response = self.check_response(
  File "C:\Users\AORUS\Documents\GitHub\Bot7k\venv\lib\site-packages\aiogram\client\session\base.py", line 120, in check_response
    raise TelegramBadRequest(method=method, message=description)
aiogram.exceptions.TelegramBadRequest: Telegram server says - Bad Request: message is not modified: specified new message content and reply markup are exactly the same as a current content and reply markup of the message

During handling of the above exception, another exception occurred:

Traceback (most recent call last):
  File "C:\Users\AORUS\Documents\GitHub\Bot7k\venv\lib\site-packages\aiogram\dispatcher\dispatcher.py", line 308, in _process_update
    response = await self.feed_update(bot, update, **kwargs)
  File "C:\Users\AORUS\Documents\GitHub\Bot7k\venv\lib\site-packages\aiogram\dispatcher\dispatcher.py", line 157, in feed_update
    response = await self.update.wrap_outer_middleware(
  File "C:\Users\AORUS\Documents\GitHub\Bot7k\venv\lib\site-packages\aiogram\dispatcher\middlewares\error.py", line 29, in __call__
    response = await self.router.propagate_event(
  File "C:\Users\AORUS\Documents\GitHub\Bot7k\venv\lib\site-packages\aiogram\dispatcher\router.py", line 116, in propagate_event
    return await observer.wrap_outer_middleware(_wrapped, event=event, data=kwargs)
  File "C:\Users\AORUS\Documents\GitHub\Bot7k\venv\lib\site-packages\aiogram\dispatcher\router.py", line 111, in _wrapped
    return await self._propagate_event(
  File "C:\Users\AORUS\Documents\GitHub\Bot7k\venv\lib\site-packages\aiogram\dispatcher\router.py", line 136, in _propagate_event
    response = await observer.trigger(event, **kwargs)
  File "C:\Users\AORUS\Documents\GitHub\Bot7k\venv\lib\site-packages\aiogram\dispatcher\event\telegram.py", line 120, in trigger
    return await wrapped_inner(event, kwargs)
  File "C:\Users\AORUS\Documents\GitHub\Bot7k\venv\lib\site-packages\aiogram\dispatcher\event\handler.py", line 42, in call
    return await wrapped()
TypeError: handle_errors() missing 1 required positional argument: 'exception'
2025-03-28 21:10:41,999 - INFO - Update id=821253777 is handled. Duration 561 ms by bot id=7597499330
2025-03-28 21:10:42,916 - INFO - Update id=821253778 is handled. Duration 297 ms by bot id=7597499330
2025-03-28 21:10:47,500 - INFO - Update id=821253779 is handled. Duration 327 ms by bot id=7597499330
2025-03-28 21:11:07,780 - INFO - Polling stopped for bot @Testo1113_Bot id=7597499330 - 'Testo123'
2025-03-28 21:11:07,780 - INFO - Polling stopped
2025-03-28 21:11:07,781 - INFO - Бот остановлен пользователем
2025-03-28 21:11:07,829 - ERROR - Task exception was never retrieved
future: <Task finished name='Task-8' coro=<UpdateMethods._keepalive_loop() done, defined at C:\Users\AORUS\Documents\GitHub\Bot7k\venv\lib\site-packages\telethon\client\updates.py:481> exception=OperationalError('database is locked')>
Traceback (most recent call last):
  File "C:\Users\AORUS\Documents\GitHub\Bot7k\venv\lib\site-packages\telethon\client\updates.py", line 517, in _keepalive_loop
    self._save_states_and_entities()
  File "C:\Users\AORUS\Documents\GitHub\Bot7k\venv\lib\site-packages\telethon\client\telegrambaseclient.py", line 694, in _save_states_and_entities
    self.session.process_entities(types.contacts.ResolvedPeer(None, [e._as_input_peer() for e in entities], []))
  File "C:\Users\AORUS\Documents\GitHub\Bot7k\venv\lib\site-packages\telethon\sessions\sqlite.py", line 301, in process_entities
    c.executemany(
sqlite3.OperationalError: database is locked
2025-03-28 21:11:10,439 - INFO - Connecting to 149.154.167.51:443/TcpFull...
2025-03-28 21:11:10,573 - INFO - Connection to 149.154.167.51:443/TcpFull complete!
2025-03-28 21:11:11,381 - INFO - Start polling
2025-03-28 21:11:11,792 - INFO - Run polling for bot @Testo1113_Bot id=7597499330 - 'Testo123'
2025-03-28 21:11:17,067 - INFO - Update id=821253780 is handled. Duration 468 ms by bot id=7597499330
2025-03-28 21:11:19,383 - INFO - Update id=821253781 is handled. Duration 171 ms by bot id=7597499330
2025-03-28 21:11:21,367 - INFO - Update id=821253782 is handled. Duration 500 ms by bot id=7597499330
2025-03-28 21:11:49,223 - INFO - Update id=821253783 is handled. Duration 438 ms by bot id=7597499330
2025-03-28 21:11:52,674 - INFO - Connecting to 149.154.167.51:443/TcpFull...
2025-03-28 21:11:52,807 - INFO - Connection to 149.154.167.51:443/TcpFull complete!
2025-03-28 21:11:58,490 - INFO - Update id=821253784 is handled. Duration 5811 ms by bot id=7597499330
2025-03-28 21:13:22,939 - WARNING - Server closed the connection: 0 bytes read on a total of 8 expected bytes
2025-03-28 21:13:22,940 - INFO - Connection closed while receiving data: 0 bytes read on a total of 8 expected bytes
2025-03-28 21:13:22,940 - INFO - Closing current connection to begin reconnect...
2025-03-28 21:13:22,940 - INFO - Connecting to 149.154.167.51:443/TcpFull...
2025-03-28 21:13:23,071 - INFO - Connection to 149.154.167.51:443/TcpFull complete!
2025-03-28 21:24:15,094 - WARNING - Server closed the connection: 0 bytes read on a total of 8 expected bytes
2025-03-28 21:24:15,094 - INFO - Connection closed while receiving data: 0 bytes read on a total of 8 expected bytes
2025-03-28 21:24:15,095 - INFO - Closing current connection to begin reconnect...
2025-03-28 21:24:15,095 - INFO - Connecting to 149.154.167.51:443/TcpFull...
2025-03-28 21:24:15,227 - INFO - Connection to 149.154.167.51:443/TcpFull complete!
2025-03-28 21:26:11,532 - WARNING - Server closed the connection: [WinError 64] Указанное сетевое имя более недоступно
2025-03-28 21:26:11,532 - INFO - Connection closed while receiving data: [WinError 64] Указанное сетевое имя более недоступно
2025-03-28 21:26:11,533 - INFO - Closing current connection to begin reconnect...
2025-03-28 21:26:11,533 - INFO - Connecting to 149.154.167.51:443/TcpFull...
2025-03-28 21:26:11,534 - INFO - <class 'ConnectionResetError'> during disconnect: [WinError 64] Указанное сетевое имя более недоступно
2025-03-28 21:26:11,666 - INFO - Connection to 149.154.167.51:443/TcpFull complete!
2025-03-28 21:26:17,323 - WARNING - Error executing high-level request after reconnect: <class 'sqlite3.OperationalError'>: database is locked
2025-03-28 21:26:22,842 - WARNING - Cannot get difference since the account is likely misusing the session: database is locked
2025-03-28 21:26:22,844 - INFO - Disconnecting from 149.154.167.51:443/TcpFull...
2025-03-28 21:26:22,847 - INFO - Disconnection from 149.154.167.51:443/TcpFull complete!
2025-03-28 21:26:22,847 - ERROR - Unhandled exception from keepalive_handle after cancelling <class '_asyncio.Task'> (<Task finished name='Task-8' coro=<UpdateMethods._keepalive_loop() done, defined at C:\Users\AORUS\Documents\GitHub\Bot7k\venv\lib\site-packages\telethon\client\updates.py:481> exception=OperationalError('database is locked')>)
Traceback (most recent call last):
  File "C:\Users\AORUS\Documents\GitHub\Bot7k\venv\lib\site-packages\telethon\helpers.py", line 176, in _cancel
    await task
  File "C:\Users\AORUS\Documents\GitHub\Bot7k\venv\lib\site-packages\telethon\client\updates.py", line 517, in _keepalive_loop
    self._save_states_and_entities()
  File "C:\Users\AORUS\Documents\GitHub\Bot7k\venv\lib\site-packages\telethon\client\telegrambaseclient.py", line 694, in _save_states_and_entities
    self.session.process_entities(types.contacts.ResolvedPeer(None, [e._as_input_peer() for e in entities], []))
  File "C:\Users\AORUS\Documents\GitHub\Bot7k\venv\lib\site-packages\telethon\sessions\sqlite.py", line 301, in process_entities
    c.executemany(
sqlite3.OperationalError: database is locked
2025-03-28 21:26:28,378 - ERROR - Task exception was never retrieved
future: <Task finished name='Task-174' coro=<TelegramBaseClient._disconnect_coro() done, defined at C:\Users\AORUS\Documents\GitHub\Bot7k\venv\lib\site-packages\telethon\client\telegrambaseclient.py:707> exception=OperationalError('database is locked')>
Traceback (most recent call last):
  File "C:\Users\AORUS\Documents\GitHub\Bot7k\venv\lib\site-packages\telethon\client\telegrambaseclient.py", line 737, in _disconnect_coro
    self._save_states_and_entities()
  File "C:\Users\AORUS\Documents\GitHub\Bot7k\venv\lib\site-packages\telethon\client\telegrambaseclient.py", line 694, in _save_states_and_entities
    self.session.process_entities(types.contacts.ResolvedPeer(None, [e._as_input_peer() for e in entities], []))
  File "C:\Users\AORUS\Documents\GitHub\Bot7k\venv\lib\site-packages\telethon\sessions\sqlite.py", line 301, in process_entities
    c.executemany(
sqlite3.OperationalError: database is locked
2025-03-28 21:35:20,343 - INFO - Polling stopped for bot @Testo1113_Bot id=7597499330 - 'Testo123'
2025-03-28 21:35:20,343 - INFO - Polling stopped
2025-03-28 21:35:20,344 - INFO - Бот остановлен пользователем
2025-03-28 21:35:22,575 - INFO - Connecting to 149.154.167.51:443/TcpFull...
2025-03-28 21:35:22,707 - INFO - Connection to 149.154.167.51:443/TcpFull complete!
2025-03-28 21:35:23,281 - INFO - Start polling
2025-03-28 21:35:23,820 - INFO - Run polling for bot @Testo1113_Bot id=7597499330 - 'Testo123'
2025-03-28 21:36:06,232 - INFO - Update id=821253785 is handled. Duration 467 ms by bot id=7597499330
2025-03-28 21:36:08,136 - INFO - Update id=821253786 is handled. Duration 250 ms by bot id=7597499330
2025-03-28 21:36:09,329 - INFO - Update id=821253787 is handled. Duration 265 ms by bot id=7597499330
2025-03-28 21:36:11,177 - INFO - Update id=821253788 is handled. Duration 156 ms by bot id=7597499330
2025-03-28 21:36:12,430 - INFO - Update id=821253789 is handled. Duration 172 ms by bot id=7597499330
2025-03-28 21:36:13,985 - INFO - Update id=821253790 is handled. Duration 295 ms by bot id=7597499330
2025-03-28 21:36:18,148 - INFO - Update id=821253791 is handled. Duration 187 ms by bot id=7597499330
2025-03-28 21:36:19,494 - INFO - Connecting to 149.154.167.51:443/TcpFull...
2025-03-28 21:36:19,624 - INFO - Connection to 149.154.167.51:443/TcpFull complete!
2025-03-28 21:36:25,287 - INFO - Update id=821253792 is handled. Duration 5797 ms by bot id=7597499330
2025-03-28 21:37:49,758 - WARNING - Server closed the connection: 0 bytes read on a total of 8 expected bytes
2025-03-28 21:37:49,758 - INFO - Connection closed while receiving data: 0 bytes read on a total of 8 expected bytes
2025-03-28 21:37:49,758 - INFO - Closing current connection to begin reconnect...
2025-03-28 21:37:49,758 - INFO - Connecting to 149.154.167.51:443/TcpFull...
2025-03-28 21:37:49,892 - INFO - Connection to 149.154.167.51:443/TcpFull complete!
2025-03-28 21:41:54,204 - INFO - Polling stopped for bot @Testo1113_Bot id=7597499330 - 'Testo123'
2025-03-28 21:41:54,204 - INFO - Polling stopped
2025-03-28 21:41:54,207 - INFO - Бот остановлен пользователем
2025-03-28 21:41:54,261 - ERROR - Task exception was never retrieved
future: <Task finished name='Task-8' coro=<UpdateMethods._keepalive_loop() done, defined at C:\Users\AORUS\Documents\GitHub\Bot7k\venv\lib\site-packages\telethon\client\updates.py:481> exception=OperationalError('database is locked')>
Traceback (most recent call last):
  File "C:\Users\AORUS\Documents\GitHub\Bot7k\venv\lib\site-packages\telethon\client\updates.py", line 517, in _keepalive_loop
    self._save_states_and_entities()
  File "C:\Users\AORUS\Documents\GitHub\Bot7k\venv\lib\site-packages\telethon\client\telegrambaseclient.py", line 694, in _save_states_and_entities
    self.session.process_entities(types.contacts.ResolvedPeer(None, [e._as_input_peer() for e in entities], []))
  File "C:\Users\AORUS\Documents\GitHub\Bot7k\venv\lib\site-packages\telethon\sessions\sqlite.py", line 301, in process_entities
    c.executemany(
sqlite3.OperationalError: database is locked
2025-03-28 21:45:08,834 - INFO - Start polling
2025-03-28 21:45:09,378 - INFO - Run polling for bot @Testo1113_Bot id=7597499330 - 'Testo123'
2025-03-28 21:45:20,806 - INFO - Update id=821253793 is handled. Duration 422 ms by bot id=7597499330
2025-03-28 21:45:24,110 - INFO - Update id=821253794 is handled. Duration 202 ms by bot id=7597499330
2025-03-28 21:45:26,638 - INFO - Update id=821253795 is handled. Duration 202 ms by bot id=7597499330
2025-03-28 21:45:38,020 - INFO - Update id=821253796 is handled. Duration 157 ms by bot id=7597499330
2025-03-28 21:45:49,457 - INFO - Connecting to 149.154.167.51:443/TcpFull...
2025-03-28 21:45:49,588 - INFO - Connection to 149.154.167.51:443/TcpFull complete!
2025-03-28 21:45:50,906 - WARNING - Telegram is having internal issues AuthRestartError: Restart the authorization process (caused by SendCodeRequest)
2025-03-28 21:45:51,111 - INFO - Cannot get difference since the account is not logged in: AuthKeyUnregisteredError
2025-03-28 21:45:51,113 - INFO - Disconnecting from 149.154.167.51:443/TcpFull...
2025-03-28 21:45:51,113 - INFO - Disconnection from 149.154.167.51:443/TcpFull complete!
2025-03-28 21:45:53,096 - INFO - Update id=821253797 is handled. Duration 3641 ms by bot id=7597499330
2025-03-28 21:50:05,571 - INFO - Update id=821253798 is handled. Duration 484 ms by bot id=7597499330
2025-03-28 21:50:15,773 - INFO - Connecting to 149.154.167.51:443/TcpFull...
2025-03-28 21:50:15,905 - INFO - Connection to 149.154.167.51:443/TcpFull complete!
2025-03-28 21:50:17,294 - INFO - Update id=821253799 is handled. Duration 1531 ms by bot id=7597499330
2025-03-28 21:50:24,679 - INFO - Update id=821253800 is handled. Duration 672 ms by bot id=7597499330
2025-03-28 21:50:28,947 - INFO - Update id=821253801 is handled. Duration 266 ms by bot id=7597499330
2025-03-28 21:50:31,733 - INFO - Update id=821253802 is handled. Duration 170 ms by bot id=7597499330
2025-03-28 21:50:33,725 - INFO - Update id=821253803 is handled. Duration 156 ms by bot id=7597499330
2025-03-28 21:50:35,190 - INFO - Update id=821253804 is handled. Duration 329 ms by bot id=7597499330
2025-03-28 21:50:39,612 - INFO - Update id=821253805 is handled. Duration 264 ms by bot id=7597499330
2025-03-28 21:50:40,785 - INFO - Connecting to 149.154.167.51:443/TcpFull...
2025-03-28 21:50:40,916 - INFO - Connection to 149.154.167.51:443/TcpFull complete!
2025-03-28 21:50:46,747 - INFO - Update id=821253806 is handled. Duration 5968 ms by bot id=7597499330
2025-03-28 21:52:12,052 - WARNING - Server closed the connection: 0 bytes read on a total of 8 expected bytes
2025-03-28 21:52:12,052 - INFO - Connection closed while receiving data: 0 bytes read on a total of 8 expected bytes
2025-03-28 21:52:12,052 - INFO - Closing current connection to begin reconnect...
2025-03-28 21:52:12,052 - INFO - Connecting to 149.154.167.51:443/TcpFull...
2025-03-28 21:52:12,183 - INFO - Connection to 149.154.167.51:443/TcpFull complete!
2025-03-28 22:01:08,887 - WARNING - Server closed the connection: 0 bytes read on a total of 8 expected bytes
2025-03-28 22:01:08,887 - INFO - Connection closed while receiving data: 0 bytes read on a total of 8 expected bytes
2025-03-28 22:01:08,887 - INFO - Closing current connection to begin reconnect...
2025-03-28 22:01:08,887 - INFO - Connecting to 149.154.167.51:443/TcpFull...
2025-03-28 22:01:09,020 - INFO - Connection to 149.154.167.51:443/TcpFull complete!
2025-03-28 22:01:19,488 - WARNING - Server closed the connection: 0 bytes read on a total of 8 expected bytes
2025-03-28 22:01:19,488 - INFO - Connection closed while receiving data: 0 bytes read on a total of 8 expected bytes
2025-03-28 22:01:19,488 - INFO - Closing current connection to begin reconnect...
2025-03-28 22:01:19,489 - INFO - Connecting to 149.154.167.51:443/TcpFull...
2025-03-28 22:01:19,621 - INFO - Connection to 149.154.167.51:443/TcpFull complete!
2025-03-28 22:01:25,288 - WARNING - Error executing high-level request after reconnect: <class 'sqlite3.OperationalError'>: database is locked
2025-03-28 22:10:19,613 - WARNING - Server closed the connection: 0 bytes read on a total of 8 expected bytes
2025-03-28 22:10:19,613 - INFO - Connection closed while receiving data: 0 bytes read on a total of 8 expected bytes
2025-03-28 22:10:19,614 - INFO - Closing current connection to begin reconnect...
2025-03-28 22:10:19,614 - INFO - Connecting to 149.154.167.51:443/TcpFull...
2025-03-28 22:10:19,745 - INFO - Connection to 149.154.167.51:443/TcpFull complete!
2025-03-28 22:10:46,291 - WARNING - Server closed the connection: [WinError 1236] Подключение к сети было разорвано локальной системой
2025-03-28 22:10:46,293 - WARNING - Server closed the connection: [WinError 1236] Подключение к сети было разорвано локальной системой
2025-03-28 22:10:46,293 - INFO - Connection closed while receiving data: [WinError 1236] Подключение к сети было разорвано локальной системой
2025-03-28 22:10:46,293 - INFO - Connection closed while receiving data: [WinError 1236] Подключение к сети было разорвано локальной системой
2025-03-28 22:10:46,293 - ERROR - Failed to fetch updates - TelegramNetworkError: HTTP Client says - ClientOSError: [WinError 1236] Подключение к сети было разорвано локальной системой
2025-03-28 22:10:46,294 - WARNING - Sleep for 1.000000 seconds and try again... (tryings = 0, bot id = 7597499330)
2025-03-28 22:10:46,300 - INFO - Closing current connection to begin reconnect...
2025-03-28 22:10:46,300 - INFO - Closing current connection to begin reconnect...
2025-03-28 22:10:46,301 - INFO - Connecting to 149.154.167.51:443/TcpFull...
2025-03-28 22:10:46,301 - INFO - Connecting to 149.154.167.51:443/TcpFull...
2025-03-28 22:10:46,302 - INFO - <class 'ConnectionAbortedError'> during disconnect: [WinError 1236] Подключение к сети было разорвано локальной системой
2025-03-28 22:10:46,302 - INFO - <class 'ConnectionAbortedError'> during disconnect: [WinError 1236] Подключение к сети было разорвано локальной системой
2025-03-28 22:10:46,303 - WARNING - Attempt 1 at connecting failed: PermissionError: [WinError 5] Отказано в доступе
2025-03-28 22:10:46,303 - WARNING - Attempt 1 at connecting failed: PermissionError: [WinError 5] Отказано в доступе
2025-03-28 22:10:47,431 - INFO - Connection to 149.154.167.51:443/TcpFull complete!
2025-03-28 22:10:53,168 - WARNING - Error executing high-level request after reconnect: <class 'sqlite3.OperationalError'>: database is locked
2025-03-28 22:10:56,425 - INFO - Connection to 149.154.167.51:443/TcpFull complete!
2025-03-28 22:10:57,789 - INFO - Connection established (tryings = 1, bot id = 7597499330)
2025-03-28 22:20:39,101 - WARNING - Server closed the connection: 0 bytes read on a total of 8 expected bytes
2025-03-28 22:20:39,101 - INFO - Connection closed while receiving data: 0 bytes read on a total of 8 expected bytes
2025-03-28 22:20:39,101 - INFO - Closing current connection to begin reconnect...
2025-03-28 22:20:39,101 - INFO - Connecting to 149.154.167.51:443/TcpFull...
2025-03-28 22:20:39,220 - INFO - Connection to 149.154.167.51:443/TcpFull complete!
2025-03-28 22:20:56,078 - WARNING - Server closed the connection: [WinError 64] Указанное сетевое имя более недоступно
2025-03-28 22:20:56,078 - INFO - Connection closed while receiving data: [WinError 64] Указанное сетевое имя более недоступно
2025-03-28 22:20:56,078 - INFO - Closing current connection to begin reconnect...
2025-03-28 22:20:56,079 - INFO - Connecting to 149.154.167.51:443/TcpFull...
2025-03-28 22:20:56,080 - INFO - <class 'ConnectionResetError'> during disconnect: [WinError 64] Указанное сетевое имя более недоступно
2025-03-28 22:20:56,204 - INFO - Connection to 149.154.167.51:443/TcpFull complete!
2025-03-28 22:21:01,865 - WARNING - Error executing high-level request after reconnect: <class 'sqlite3.OperationalError'>: database is locked
2025-03-28 22:28:32,491 - ERROR - Failed to fetch updates - TelegramNetworkError: HTTP Client says - ClientOSError: [WinError 1236] Подключение к сети было разорвано локальной системой
2025-03-28 22:28:32,492 - WARNING - Sleep for 1.000000 seconds and try again... (tryings = 0, bot id = 7597499330)
2025-03-28 22:28:33,451 - WARNING - Server closed the connection: [WinError 1236] Подключение к сети было разорвано локальной системой
2025-03-28 22:28:33,451 - INFO - Connection closed while receiving data: [WinError 1236] Подключение к сети было разорвано локальной системой
2025-03-28 22:28:33,451 - INFO - Closing current connection to begin reconnect...
2025-03-28 22:28:33,451 - INFO - Connecting to 149.154.167.51:443/TcpFull...
2025-03-28 22:28:33,451 - INFO - <class 'ConnectionAbortedError'> during disconnect: [WinError 1236] Подключение к сети было разорвано локальной системой
2025-03-28 22:28:33,453 - WARNING - Attempt 1 at connecting failed: PermissionError: [WinError 5] Отказано в доступе
2025-03-28 22:28:33,498 - ERROR - Failed to fetch updates - TelegramNetworkError: HTTP Client says - ClientConnectorError: Cannot connect to host api.telegram.org:443 ssl:default [Отказано в доступе]
2025-03-28 22:28:33,498 - WARNING - Sleep for 1.361916 seconds and try again... (tryings = 1, bot id = 7597499330)
2025-03-28 22:28:34,466 - WARNING - Attempt 2 at connecting failed: PermissionError: [WinError 5] Отказано в доступе
2025-03-28 22:28:34,875 - ERROR - Failed to fetch updates - TelegramNetworkError: HTTP Client says - ClientConnectorError: Cannot connect to host api.telegram.org:443 ssl:default [Отказано в доступе]
2025-03-28 22:28:34,876 - WARNING - Sleep for 1.752177 seconds and try again... (tryings = 2, bot id = 7597499330)
2025-03-28 22:28:35,476 - WARNING - Attempt 3 at connecting failed: PermissionError: [WinError 5] Отказано в доступе
2025-03-28 22:28:36,487 - WARNING - Attempt 4 at connecting failed: OSError: [WinError 1232] Сетевая папка недоступна. За информацией о разрешении проблем в сети обратитесь к справочной системе Windows
2025-03-28 22:28:36,642 - ERROR - Failed to fetch updates - TelegramNetworkError: HTTP Client says - ClientConnectorError: Cannot connect to host api.telegram.org:443 ssl:default [Сетевая папка недоступна. За информацией о разрешении проблем в сети обратитесь к справочной системе Windows]
2025-03-28 22:28:36,644 - WARNING - Sleep for 2.326407 seconds and try again... (tryings = 3, bot id = 7597499330)
2025-03-28 22:28:37,498 - WARNING - Attempt 5 at connecting failed: OSError: [WinError 1232] Сетевая папка недоступна. За информацией о разрешении проблем в сети обратитесь к справочной системе Windows
2025-03-28 22:28:38,510 - WARNING - Attempt 6 at connecting failed: OSError: [WinError 1232] Сетевая папка недоступна. За информацией о разрешении проблем в сети обратитесь к справочной системе Windows
2025-03-28 22:28:38,991 - ERROR - Failed to fetch updates - TelegramNetworkError: HTTP Client says - ClientConnectorError: Cannot connect to host api.telegram.org:443 ssl:default [Сетевая папка недоступна. За информацией о разрешении проблем в сети обратитесь к справочной системе Windows]
2025-03-28 22:28:38,992 - WARNING - Sleep for 3.098104 seconds and try again... (tryings = 4, bot id = 7597499330)
2025-03-28 22:28:39,519 - INFO - Failed reconnection attempt 1 with ConnectionError
2025-03-28 22:28:40,528 - INFO - Connecting to 149.154.167.51:443/TcpFull...
2025-03-28 22:28:40,671 - INFO - Connection to 149.154.167.51:443/TcpFull complete!
2025-03-28 22:28:46,388 - WARNING - Error executing high-level request after reconnect: <class 'sqlite3.OperationalError'>: database is locked
2025-03-28 22:28:56,952 - INFO - Connection established (tryings = 5, bot id = 7597499330)
2025-03-28 22:47:04,840 - WARNING - Server closed the connection: 0 bytes read on a total of 8 expected bytes
2025-03-28 22:47:04,840 - INFO - Connection closed while receiving data: 0 bytes read on a total of 8 expected bytes
2025-03-28 22:47:04,841 - INFO - Closing current connection to begin reconnect...
2025-03-28 22:47:04,841 - INFO - Connecting to 149.154.167.51:443/TcpFull...
2025-03-28 22:47:04,989 - INFO - Connection to 149.154.167.51:443/TcpFull complete!
2025-03-28 22:47:10,683 - WARNING - Error executing high-level request after reconnect: <class 'sqlite3.OperationalError'>: database is locked
2025-03-28 22:48:58,021 - WARNING - Server closed the connection: [WinError 1236] Подключение к сети было разорвано локальной системой
2025-03-28 22:48:58,022 - ERROR - Failed to fetch updates - TelegramNetworkError: HTTP Client says - ClientOSError: [WinError 1236] Подключение к сети было разорвано локальной системой
2025-03-28 22:48:58,022 - WARNING - Sleep for 1.000000 seconds and try again... (tryings = 0, bot id = 7597499330)
2025-03-28 22:48:58,022 - INFO - Connection closed while receiving data: [WinError 1236] Подключение к сети было разорвано локальной системой
2025-03-28 22:48:58,022 - INFO - Closing current connection to begin reconnect...
2025-03-28 22:48:58,023 - INFO - Connecting to 149.154.167.51:443/TcpFull...
2025-03-28 22:48:58,023 - INFO - <class 'ConnectionAbortedError'> during disconnect: [WinError 1236] Подключение к сети было разорвано локальной системой
2025-03-28 22:48:58,023 - WARNING - Attempt 1 at connecting failed: PermissionError: [WinError 5] Отказано в доступе
2025-03-28 22:48:59,155 - INFO - Connection to 149.154.167.51:443/TcpFull complete!
2025-03-28 22:49:04,795 - WARNING - Error executing high-level request after reconnect: <class 'sqlite3.OperationalError'>: database is locked
2025-03-28 22:49:04,801 - WARNING - Server closed the connection: [WinError 1236] Подключение к сети было разорвано локальной системой
2025-03-28 22:49:04,802 - INFO - Connection closed while receiving data: [WinError 1236] Подключение к сети было разорвано локальной системой
2025-03-28 22:49:04,802 - INFO - Closing current connection to begin reconnect...
2025-03-28 22:49:04,802 - ERROR - Failed to fetch updates - TelegramNetworkError: HTTP Client says - ClientOSError: [WinError 10054] Удаленный хост принудительно разорвал существующее подключение
2025-03-28 22:49:04,802 - WARNING - Sleep for 1.469498 seconds and try again... (tryings = 1, bot id = 7597499330)
2025-03-28 22:49:04,803 - INFO - Connecting to 149.154.167.51:443/TcpFull...
2025-03-28 22:49:04,803 - INFO - <class 'ConnectionAbortedError'> during disconnect: [WinError 1236] Подключение к сети было разорвано локальной системой
2025-03-28 22:49:04,804 - WARNING - Attempt 1 at connecting failed: OSError: [WinError 1232] Сетевая папка недоступна. За информацией о разрешении проблем в сети обратитесь к справочной системе Windows
2025-03-28 22:49:05,817 - WARNING - Attempt 2 at connecting failed: OSError: [WinError 1232] Сетевая папка недоступна. За информацией о разрешении проблем в сети обратитесь к справочной системе Windows
2025-03-28 22:49:06,286 - ERROR - Failed to fetch updates - TelegramNetworkError: HTTP Client says - ClientConnectorError: Cannot connect to host api.telegram.org:443 ssl:default [Сетевая папка недоступна. За информацией о разрешении проблем в сети обратитесь к справочной системе Windows]
2025-03-28 22:49:06,286 - WARNING - Sleep for 1.890905 seconds and try again... (tryings = 2, bot id = 7597499330)
2025-03-28 22:49:06,830 - WARNING - Attempt 3 at connecting failed: OSError: [WinError 1232] Сетевая папка недоступна. За информацией о разрешении проблем в сети обратитесь к справочной системе Windows
2025-03-28 22:49:07,974 - INFO - Connection to 149.154.167.51:443/TcpFull complete!
2025-03-28 22:49:13,647 - WARNING - Error executing high-level request after reconnect: <class 'sqlite3.OperationalError'>: database is locked
2025-03-28 22:49:24,183 - INFO - Connection established (tryings = 3, bot id = 7597499330)
2025-03-28 22:50:48,348 - INFO - Polling stopped
2025-03-28 22:50:48,349 - INFO - Polling stopped for bot @Testo1113_Bot id=7597499330 - 'Testo123'
2025-03-28 22:50:48,354 - INFO - Бот остановлен пользователем
2025-03-28 22:50:48,503 - ERROR - Task exception was never retrieved
future: <Task finished name='Task-74' coro=<UpdateMethods._keepalive_loop() done, defined at C:\Users\AORUS\Documents\GitHub\Bot7k\venv\lib\site-packages\telethon\client\updates.py:481> exception=OperationalError('database is locked')>
Traceback (most recent call last):
  File "C:\Users\AORUS\Documents\GitHub\Bot7k\venv\lib\site-packages\telethon\client\updates.py", line 517, in _keepalive_loop
    self._save_states_and_entities()
  File "C:\Users\AORUS\Documents\GitHub\Bot7k\venv\lib\site-packages\telethon\client\telegrambaseclient.py", line 694, in _save_states_and_entities
    self.session.process_entities(types.contacts.ResolvedPeer(None, [e._as_input_peer() for e in entities], []))
  File "C:\Users\AORUS\Documents\GitHub\Bot7k\venv\lib\site-packages\telethon\sessions\sqlite.py", line 301, in process_entities
    c.executemany(
sqlite3.OperationalError: database is locked
2025-03-28 22:50:50,646 - INFO - Start polling
2025-03-28 22:50:51,071 - INFO - Run polling for bot @Testo1113_Bot id=7597499330 - 'Testo123'
2025-03-28 22:51:23,223 - INFO - Update id=821253807 is handled. Duration 625 ms by bot id=7597499330
2025-03-28 22:51:26,784 - INFO - Update id=821253808 is handled. Duration 311 ms by bot id=7597499330
2025-03-28 22:51:27,950 - INFO - Update id=821253809 is handled. Duration 219 ms by bot id=7597499330
2025-03-28 22:51:40,647 - INFO - Update id=821253810 is handled. Duration 187 ms by bot id=7597499330
2025-03-28 22:51:41,978 - INFO - Update id=821253811 is handled. Duration 156 ms by bot id=7597499330
2025-03-28 22:51:42,625 - INFO - Update id=821253812 is handled. Duration 218 ms by bot id=7597499330
2025-03-28 22:51:49,103 - INFO - Connecting to 149.154.167.51:443/TcpFull...
2025-03-28 22:51:49,238 - INFO - Connection to 149.154.167.51:443/TcpFull complete!
2025-03-28 22:51:50,386 - WARNING - Telegram is having internal issues AuthRestartError: Restart the authorization process (caused by SendCodeRequest)
2025-03-28 22:51:50,522 - INFO - Cannot get difference since the account is not logged in: AuthKeyUnregisteredError
2025-03-28 22:51:50,523 - INFO - Disconnecting from 149.154.167.51:443/TcpFull...
2025-03-28 22:51:50,523 - INFO - Disconnection from 149.154.167.51:443/TcpFull complete!
2025-03-28 22:51:52,595 - INFO - Update id=821253813 is handled. Duration 3500 ms by bot id=7597499330
2025-03-28 22:52:04,890 - INFO - Update id=821253814 is handled. Duration 171 ms by bot id=7597499330
2025-03-28 22:52:15,344 - INFO - Connecting to 149.154.167.51:443/TcpFull...
2025-03-28 22:52:15,476 - INFO - Connection to 149.154.167.51:443/TcpFull complete!
2025-03-28 22:52:16,632 - INFO - Update id=821253815 is handled. Duration 1280 ms by bot id=7597499330
2025-03-28 22:52:23,713 - INFO - Update id=821253816 is handled. Duration 781 ms by bot id=7597499330
2025-03-28 22:52:31,960 - INFO - Update id=821253817 is handled. Duration 156 ms by bot id=7597499330
2025-03-28 22:52:33,625 - INFO - Update id=821253818 is handled. Duration 250 ms by bot id=7597499330
2025-03-28 22:52:35,810 - INFO - Update id=821253819 is handled. Duration 375 ms by bot id=7597499330
2025-03-28 22:53:01,402 - INFO - Update id=821253820 is handled. Duration 452 ms by bot id=7597499330
2025-03-28 22:53:03,380 - INFO - Connecting to 149.154.167.51:443/TcpFull...
2025-03-28 22:53:03,512 - INFO - Connection to 149.154.167.51:443/TcpFull complete!
2025-03-28 22:53:09,284 - INFO - Update id=821253821 is handled. Duration 5906 ms by bot id=7597499330
2025-03-28 22:53:37,969 - INFO - Got difference for account updates
2025-03-28 22:53:40,585 - INFO - Update id=821253822 is not handled. Duration 0 ms by bot id=7597499330
2025-03-28 22:53:48,659 - INFO - Update id=821253823 is not handled. Duration 0 ms by bot id=7597499330
2025-03-28 22:53:49,537 - INFO - Update id=821253824 is not handled. Duration 0 ms by bot id=7597499330
2025-03-28 22:53:50,253 - INFO - Update id=821253825 is not handled. Duration 0 ms by bot id=7597499330
2025-03-28 22:53:51,532 - INFO - Update id=821253826 is not handled. Duration 15 ms by bot id=7597499330
2025-03-28 22:53:59,083 - ERROR - Task was destroyed but it is pending!
task: <Task pending name='Task-87' coro=<Connection._send_loop() running at C:\Users\AORUS\Documents\GitHub\Bot7k\venv\lib\site-packages\telethon\network\connection\connection.py:322> wait_for=<Future pending cb=[Task.task_wakeup()]>>
2025-03-28 22:53:59,083 - ERROR - Task was destroyed but it is pending!
task: <Task pending name='Task-88' coro=<Connection._recv_loop() running at C:\Users\AORUS\Documents\GitHub\Bot7k\venv\lib\site-packages\telethon\network\connection\connection.py:341> wait_for=<Future pending cb=[Task.task_wakeup()]>>
2025-03-28 22:53:59,083 - ERROR - Task was destroyed but it is pending!
task: <Task pending name='Task-89' coro=<MTProtoSender._send_loop() running at C:\Users\AORUS\Documents\GitHub\Bot7k\venv\lib\site-packages\telethon\network\mtprotosender.py:464> wait_for=<Future pending cb=[Task.task_wakeup()]>>
2025-03-28 22:53:59,083 - ERROR - Task was destroyed but it is pending!
task: <Task pending name='Task-90' coro=<MTProtoSender._recv_loop() running at C:\Users\AORUS\Documents\GitHub\Bot7k\venv\lib\site-packages\telethon\network\mtprotosender.py:507> wait_for=<Future pending cb=[Task.task_wakeup()]>>
2025-03-28 22:53:59,303 - INFO - Update id=821253827 is handled. Duration 656 ms by bot id=7597499330
2025-03-28 22:54:01,852 - INFO - Update id=821253828 is handled. Duration 422 ms by bot id=7597499330
2025-03-28 22:54:03,208 - INFO - Update id=821253829 is handled. Duration 297 ms by bot id=7597499330
2025-03-28 23:05:09,448 - WARNING - Server closed the connection: [WinError 1236] Подключение к сети было разорвано локальной системой
2025-03-28 23:05:09,448 - ERROR - Failed to fetch updates - TelegramNetworkError: HTTP Client says - ClientOSError: [WinError 1236] Подключение к сети было разорвано локальной системой
2025-03-28 23:05:09,449 - WARNING - Sleep for 1.000000 seconds and try again... (tryings = 0, bot id = 7597499330)
2025-03-28 23:05:09,449 - INFO - Connection closed while receiving data: [WinError 1236] Подключение к сети было разорвано локальной системой
2025-03-28 23:05:09,449 - INFO - Closing current connection to begin reconnect...
2025-03-28 23:05:09,449 - INFO - Connecting to 149.154.167.51:443/TcpFull...
2025-03-28 23:05:09,449 - INFO - <class 'ConnectionAbortedError'> during disconnect: [WinError 1236] Подключение к сети было разорвано локальной системой
2025-03-28 23:05:09,451 - WARNING - Attempt 1 at connecting failed: PermissionError: [WinError 5] Отказано в доступе
2025-03-28 23:05:10,580 - INFO - Connection to 149.154.167.51:443/TcpFull complete!
2025-03-28 23:05:20,826 - INFO - Connection established (tryings = 1, bot id = 7597499330)
2025-03-28 23:06:33,538 - INFO - Polling stopped
2025-03-28 23:06:33,538 - INFO - Polling stopped for bot @Testo1113_Bot id=7597499330 - 'Testo123'
2025-03-28 23:06:33,540 - INFO - Бот остановлен пользователем
2025-03-28 23:06:38,762 - INFO - Connecting to 149.154.167.51:443/TcpFull...
2025-03-28 23:06:38,893 - INFO - Connection to 149.154.167.51:443/TcpFull complete!
2025-03-28 23:06:39,454 - INFO - Start polling
2025-03-28 23:06:39,843 - INFO - Run polling for bot @Testo1113_Bot id=7597499330 - 'Testo123'
2025-03-28 23:06:45,700 - INFO - Update id=821253830 is handled. Duration 453 ms by bot id=7597499330
2025-03-28 23:06:47,570 - INFO - Update id=821253831 is handled. Duration 157 ms by bot id=7597499330
2025-03-28 23:06:48,839 - INFO - Update id=821253832 is handled. Duration 188 ms by bot id=7597499330
2025-03-28 23:06:51,449 - INFO - Update id=821253833 is handled. Duration 187 ms by bot id=7597499330
2025-03-28 23:06:53,065 - INFO - Update id=821253834 is handled. Duration 172 ms by bot id=7597499330
2025-03-28 23:06:54,964 - INFO - Update id=821253835 is handled. Duration 406 ms by bot id=7597499330
2025-03-28 23:07:02,475 - INFO - Update id=821253836 is handled. Duration 172 ms by bot id=7597499330
2025-03-28 23:07:04,122 - INFO - Connecting to 149.154.167.51:443/TcpFull...
2025-03-28 23:07:04,259 - INFO - Connection to 149.154.167.51:443/TcpFull complete!
2025-03-28 23:07:09,950 - INFO - Update id=821253837 is handled. Duration 5844 ms by bot id=7597499330
2025-03-28 23:07:19,895 - INFO - Update id=821253838 is not handled. Duration 0 ms by bot id=7597499330
2025-03-28 23:07:20,942 - INFO - Update id=821253839 is not handled. Duration 0 ms by bot id=7597499330
2025-03-28 23:07:45,195 - INFO - Update id=821253840 is not handled. Duration 0 ms by bot id=7597499330
2025-03-28 23:07:46,878 - ERROR - Task was destroyed but it is pending!
task: <Task pending name='Task-49' coro=<Connection._send_loop() running at C:\Users\AORUS\Documents\GitHub\Bot7k\venv\lib\site-packages\telethon\network\connection\connection.py:322> wait_for=<Future pending cb=[Task.task_wakeup()]>>
2025-03-28 23:07:46,878 - ERROR - Task was destroyed but it is pending!
task: <Task pending name='Task-50' coro=<Connection._recv_loop() running at C:\Users\AORUS\Documents\GitHub\Bot7k\venv\lib\site-packages\telethon\network\connection\connection.py:341> wait_for=<Future pending cb=[Task.task_wakeup()]>>
2025-03-28 23:07:46,878 - ERROR - Task was destroyed but it is pending!
task: <Task pending name='Task-51' coro=<MTProtoSender._send_loop() running at C:\Users\AORUS\Documents\GitHub\Bot7k\venv\lib\site-packages\telethon\network\mtprotosender.py:464> wait_for=<Future pending cb=[Task.task_wakeup()]>>
2025-03-28 23:07:46,878 - ERROR - Task was destroyed but it is pending!
task: <Task pending name='Task-52' coro=<MTProtoSender._recv_loop() running at C:\Users\AORUS\Documents\GitHub\Bot7k\venv\lib\site-packages\telethon\network\mtprotosender.py:507> wait_for=<Future pending cb=[Task.task_wakeup()]>>
2025-03-28 23:07:47,171 - INFO - Update id=821253841 is handled. Duration 781 ms by bot id=7597499330
2025-03-28 23:07:51,236 - INFO - Update id=821253842 is not handled. Duration 14 ms by bot id=7597499330
2025-03-28 23:07:51,443 - INFO - Update id=821253843 is not handled. Duration 0 ms by bot id=7597499330
2025-03-28 23:07:54,626 - INFO - Update id=821253844 is handled. Duration 155 ms by bot id=7597499330
2025-03-28 23:07:56,485 - INFO - Update id=821253845 is handled. Duration 139 ms by bot id=7597499330
2025-03-28 23:08:00,088 - INFO - Update id=821253846 is handled. Duration 172 ms by bot id=7597499330
2025-03-28 23:08:02,139 - INFO - Update id=821253847 is handled. Duration 234 ms by bot id=7597499330
2025-03-28 23:08:08,943 - INFO - Update id=821253848 is handled. Duration 250 ms by bot id=7597499330
2025-03-28 23:08:11,470 - INFO - Update id=821253849 is handled. Duration 281 ms by bot id=7597499330
2025-03-28 23:08:36,850 - INFO - Update id=821253850 is handled. Duration 485 ms by bot id=7597499330
2025-03-28 23:08:39,262 - INFO - Connecting to 149.154.167.51:443/TcpFull...
2025-03-28 23:08:39,388 - INFO - Connection to 149.154.167.51:443/TcpFull complete!
2025-03-28 23:08:40,942 - INFO - Update id=821253851 is handled. Duration 1688 ms by bot id=7597499330
2025-03-28 23:09:12,407 - INFO - Update id=821253852 is handled. Duration 422 ms by bot id=7597499330
2025-03-28 23:09:15,760 - INFO - Update id=821253853 is handled. Duration 141 ms by bot id=7597499330
2025-03-28 23:09:17,986 - INFO - Update id=821253854 is handled. Duration 467 ms by bot id=7597499330
2025-03-28 23:09:22,326 - INFO - Update id=821253855 is handled. Duration 203 ms by bot id=7597499330
2025-03-28 23:09:23,758 - INFO - Connecting to 149.154.167.51:443/TcpFull...
2025-03-28 23:09:23,876 - INFO - Connection to 149.154.167.51:443/TcpFull complete!
2025-03-28 23:09:29,543 - INFO - Update id=821253856 is handled. Duration 5797 ms by bot id=7597499330
2025-03-28 23:09:37,698 - INFO - Update id=821253857 is handled. Duration 172 ms by bot id=7597499330
2025-03-28 23:09:45,199 - INFO - Update id=821253858 is handled. Duration 187 ms by bot id=7597499330
2025-03-28 23:09:45,839 - INFO - Update id=821253859 is handled. Duration 233 ms by bot id=7597499330
2025-03-28 23:09:48,391 - INFO - Update id=821253860 is handled. Duration 282 ms by bot id=7597499330
2025-03-28 23:09:55,865 - INFO - Update id=821253861 is handled. Duration 139 ms by bot id=7597499330
2025-03-28 23:09:57,820 - INFO - Connecting to 149.154.167.51:443/TcpFull...
2025-03-28 23:09:57,952 - INFO - Connection to 149.154.167.51:443/TcpFull complete!
2025-03-28 23:09:59,259 - INFO - Update id=821253862 is handled. Duration 1436 ms by bot id=7597499330
2025-03-28 23:10:53,995 - WARNING - Server closed the connection: 0 bytes read on a total of 8 expected bytes
2025-03-28 23:10:53,995 - INFO - Connection closed while receiving data: 0 bytes read on a total of 8 expected bytes
2025-03-28 23:10:53,995 - INFO - Closing current connection to begin reconnect...
2025-03-28 23:10:53,996 - INFO - Connecting to 149.154.167.51:443/TcpFull...
2025-03-28 23:10:54,114 - INFO - Connection to 149.154.167.51:443/TcpFull complete!
2025-03-28 23:10:59,881 - WARNING - Error executing high-level request after reconnect: <class 'sqlite3.OperationalError'>: database is locked
2025-03-28 23:11:34,485 - INFO - Update id=821253863 is handled. Duration 467 ms by bot id=7597499330
2025-03-28 23:11:36,551 - INFO - Update id=821253864 is handled. Duration 468 ms by bot id=7597499330
2025-03-28 23:11:39,130 - INFO - Update id=821253865 is handled. Duration 155 ms by bot id=7597499330
2025-03-28 23:11:41,248 - INFO - Connecting to 149.154.167.51:443/TcpFull...
2025-03-28 23:11:41,374 - INFO - Connection to 149.154.167.51:443/TcpFull complete!
2025-03-28 23:11:41,380 - ERROR - Task was destroyed but it is pending!
task: <Task pending name='Task-216' coro=<Connection._send_loop() done, defined at C:\Users\AORUS\Documents\GitHub\Bot7k\venv\lib\site-packages\telethon\network\connection\connection.py:316> wait_for=<Future cancelled>>
2025-03-28 23:11:41,382 - ERROR - Task was destroyed but it is pending!
task: <Task pending name='Task-217' coro=<Connection._recv_loop() running at C:\Users\AORUS\Documents\GitHub\Bot7k\venv\lib\site-packages\telethon\network\connection\connection.py:361> wait_for=<Future pending cb=[Task.task_wakeup()]>>
2025-03-28 23:11:41,382 - ERROR - Task was destroyed but it is pending!
task: <Task pending name='Task-218' coro=<MTProtoSender._send_loop() done, defined at C:\Users\AORUS\Documents\GitHub\Bot7k\venv\lib\site-packages\telethon\network\mtprotosender.py:446> wait_for=<Future pending cb=[Task.task_wakeup()]>>
2025-03-28 23:11:41,382 - ERROR - Task was destroyed but it is pending!
task: <Task pending name='Task-219' coro=<MTProtoSender._recv_loop() done, defined at C:\Users\AORUS\Documents\GitHub\Bot7k\venv\lib\site-packages\telethon\network\mtprotosender.py:497> wait_for=<Future cancelled>>
2025-03-28 23:11:42,709 - INFO - Update id=821253866 is handled. Duration 1469 ms by bot id=7597499330
2025-03-28 23:11:53,400 - INFO - Update id=821253867 is handled. Duration 234 ms by bot id=7597499330
2025-03-28 23:11:56,134 - INFO - Update id=821253868 is handled. Duration 358 ms by bot id=7597499330
2025-03-28 23:12:05,722 - INFO - Update id=821253869 is handled. Duration 281 ms by bot id=7597499330
2025-03-28 23:12:07,381 - INFO - Connecting to 149.154.167.51:443/TcpFull...
2025-03-28 23:12:07,499 - INFO - Connection to 149.154.167.51:443/TcpFull complete!
2025-03-28 23:12:13,149 - INFO - Update id=821253870 is handled. Duration 5766 ms by bot id=7597499330
2025-03-28 23:12:36,009 - INFO - Update id=821253871 is handled. Duration 421 ms by bot id=7597499330
2025-03-28 23:12:38,111 - INFO - Update id=821253872 is handled. Duration 155 ms by bot id=7597499330
2025-03-28 23:12:41,559 - INFO - Update id=821253873 is handled. Duration 422 ms by bot id=7597499330
2025-03-28 23:12:47,731 - INFO - Update id=821253874 is handled. Duration 170 ms by bot id=7597499330
2025-03-28 23:12:51,341 - INFO - Connecting to 149.154.167.51:443/TcpFull...
2025-03-28 23:12:51,475 - INFO - Connection to 149.154.167.51:443/TcpFull complete!
2025-03-28 23:12:52,441 - INFO - Update id=821253875 is handled. Duration 1109 ms by bot id=7597499330
2025-03-28 23:12:54,955 - INFO - Update id=821253876 is not handled. Duration 0 ms by bot id=7597499330
2025-03-28 23:12:58,945 - INFO - Update id=821253877 is not handled. Duration 0 ms by bot id=7597499330
2025-03-28 23:13:02,441 - INFO - Update id=821253878 is handled. Duration 188 ms by bot id=7597499330
2025-03-28 23:13:03,951 - INFO - Update id=821253879 is handled. Duration 219 ms by bot id=7597499330
2025-03-28 23:13:06,069 - INFO - Update id=821253880 is handled. Duration 407 ms by bot id=7597499330
2025-03-28 23:13:08,051 - INFO - Update id=821253881 is handled. Duration 172 ms by bot id=7597499330
2025-03-28 23:13:09,931 - INFO - Connecting to 149.154.167.51:443/TcpFull...
2025-03-28 23:13:10,049 - INFO - Connection to 149.154.167.51:443/TcpFull complete!
2025-03-28 23:13:15,710 - INFO - Update id=821253882 is handled. Duration 5781 ms by bot id=7597499330
2025-03-28 23:13:22,444 - ERROR - Task was destroyed but it is pending!
task: <Task pending name='Task-263' coro=<Connection._send_loop() running at C:\Users\AORUS\Documents\GitHub\Bot7k\venv\lib\site-packages\telethon\network\connection\connection.py:322> wait_for=<Future pending cb=[Task.task_wakeup()]>>
2025-03-28 23:13:22,445 - ERROR - Task was destroyed but it is pending!
task: <Task pending name='Task-264' coro=<Connection._recv_loop() running at C:\Users\AORUS\Documents\GitHub\Bot7k\venv\lib\site-packages\telethon\network\connection\connection.py:341> wait_for=<Future pending cb=[Task.task_wakeup()]>>
2025-03-28 23:13:22,445 - ERROR - Task was destroyed but it is pending!
task: <Task pending name='Task-265' coro=<MTProtoSender._send_loop() running at C:\Users\AORUS\Documents\GitHub\Bot7k\venv\lib\site-packages\telethon\network\mtprotosender.py:464> wait_for=<Future pending cb=[Task.task_wakeup()]>>
2025-03-28 23:13:22,445 - ERROR - Task was destroyed but it is pending!
task: <Task pending name='Task-266' coro=<MTProtoSender._recv_loop() running at C:\Users\AORUS\Documents\GitHub\Bot7k\venv\lib\site-packages\telethon\network\mtprotosender.py:507> wait_for=<Future pending cb=[Task.task_wakeup()]>>
2025-03-28 23:13:22,455 - ERROR - Task was destroyed but it is pending!
task: <Task pending name='Task-329' coro=<Connection._send_loop() done, defined at C:\Users\AORUS\Documents\GitHub\Bot7k\venv\lib\site-packages\telethon\network\connection\connection.py:316> wait_for=<Future cancelled>>
2025-03-28 23:13:22,457 - ERROR - Task was destroyed but it is pending!
task: <Task pending name='Task-330' coro=<Connection._recv_loop() running at C:\Users\AORUS\Documents\GitHub\Bot7k\venv\lib\site-packages\telethon\network\connection\connection.py:361> wait_for=<Future pending cb=[Task.task_wakeup()]>>
2025-03-28 23:13:22,457 - ERROR - Task was destroyed but it is pending!
task: <Task pending name='Task-331' coro=<MTProtoSender._send_loop() done, defined at C:\Users\AORUS\Documents\GitHub\Bot7k\venv\lib\site-packages\telethon\network\mtprotosender.py:446> wait_for=<Future pending cb=[Task.task_wakeup()]>>
2025-03-28 23:13:22,457 - ERROR - Task was destroyed but it is pending!
task: <Task pending name='Task-332' coro=<MTProtoSender._recv_loop() done, defined at C:\Users\AORUS\Documents\GitHub\Bot7k\venv\lib\site-packages\telethon\network\mtprotosender.py:497> wait_for=<Future cancelled>>
2025-03-28 23:13:22,623 - INFO - Update id=821253883 is handled. Duration 186 ms by bot id=7597499330
2025-03-28 23:13:29,670 - INFO - Update id=821253884 is handled. Duration 172 ms by bot id=7597499330
2025-03-28 23:13:31,944 - INFO - Update id=821253885 is handled. Duration 359 ms by bot id=7597499330
2025-03-28 23:13:33,724 - INFO - Update id=821253886 is handled. Duration 172 ms by bot id=7597499330
2025-03-28 23:13:35,329 - INFO - Connecting to 149.154.167.51:443/TcpFull...
2025-03-28 23:13:35,456 - INFO - Connection to 149.154.167.51:443/TcpFull complete!
2025-03-28 23:13:41,239 - INFO - Update id=821253887 is handled. Duration 5920 ms by bot id=7597499330
2025-03-28 23:15:05,585 - WARNING - Server closed the connection: 0 bytes read on a total of 8 expected bytes
2025-03-28 23:15:05,585 - INFO - Connection closed while receiving data: 0 bytes read on a total of 8 expected bytes
2025-03-28 23:15:05,585 - INFO - Closing current connection to begin reconnect...
2025-03-28 23:15:05,585 - INFO - Connecting to 149.154.167.51:443/TcpFull...
2025-03-28 23:15:05,717 - INFO - Connection to 149.154.167.51:443/TcpFull complete!
2025-03-28 23:15:06,972 - ERROR - Task was destroyed but it is pending!
task: <Task pending name='Task-383' coro=<Connection._send_loop() done, defined at C:\Users\AORUS\Documents\GitHub\Bot7k\venv\lib\site-packages\telethon\network\connection\connection.py:316> wait_for=<Future cancelled>>
2025-03-28 23:15:06,974 - ERROR - Task was destroyed but it is pending!
task: <Task pending name='Task-384' coro=<Connection._recv_loop() running at C:\Users\AORUS\Documents\GitHub\Bot7k\venv\lib\site-packages\telethon\network\connection\connection.py:361> wait_for=<Future pending cb=[Task.task_wakeup()]>>
2025-03-28 23:15:06,974 - ERROR - Task was destroyed but it is pending!
task: <Task pending name='Task-385' coro=<MTProtoSender._send_loop() done, defined at C:\Users\AORUS\Documents\GitHub\Bot7k\venv\lib\site-packages\telethon\network\mtprotosender.py:446> wait_for=<Future pending cb=[Task.task_wakeup()]>>
2025-03-28 23:15:06,974 - ERROR - Task was destroyed but it is pending!
task: <Task pending name='Task-386' coro=<MTProtoSender._recv_loop() done, defined at C:\Users\AORUS\Documents\GitHub\Bot7k\venv\lib\site-packages\telethon\network\mtprotosender.py:497> wait_for=<Future cancelled>>
2025-03-28 23:15:07,406 - INFO - Update id=821253888 is handled. Duration 436 ms by bot id=7597499330
2025-03-28 23:15:10,102 - INFO - Update id=821253889 is handled. Duration 172 ms by bot id=7597499330
2025-03-28 23:15:11,511 - INFO - Update id=821253890 is handled. Duration 171 ms by bot id=7597499330
2025-03-28 23:15:20,433 - INFO - Connecting to 149.154.167.51:443/TcpFull...
2025-03-28 23:15:20,562 - INFO - Connection to 149.154.167.51:443/TcpFull complete!
2025-03-28 23:15:21,489 - INFO - Update id=821253891 is handled. Duration 1061 ms by bot id=7597499330
2025-03-28 23:15:58,205 - INFO - Update id=821253892 is handled. Duration 469 ms by bot id=7597499330
2025-03-28 23:15:58,288 - INFO - Update id=821253894 is handled. Duration 436 ms by bot id=7597499330
2025-03-28 23:15:58,324 - INFO - Update id=821253893 is handled. Duration 483 ms by bot id=7597499330
2025-03-28 23:15:58,359 - INFO - Update id=821253896 is handled. Duration 514 ms by bot id=7597499330
2025-03-28 23:15:58,394 - INFO - Update id=821253895 is handled. Duration 546 ms by bot id=7597499330
2025-03-28 23:15:58,460 - INFO - Update id=821253897 is handled. Duration 469 ms by bot id=7597499330
2025-03-28 23:15:58,581 - INFO - Update id=821253899 is handled. Duration 187 ms by bot id=7597499330
2025-03-28 23:15:58,675 - INFO - Update id=821253898 is handled. Duration 468 ms by bot id=7597499330
2025-03-28 23:15:58,780 - INFO - Update id=821253900 is handled. Duration 217 ms by bot id=7597499330
2025-03-28 23:16:03,942 - INFO - Update id=821253901 is handled. Duration 141 ms by bot id=7597499330
2025-03-28 23:16:07,673 - INFO - Update id=821253902 is handled. Duration 281 ms by bot id=7597499330
2025-03-28 23:20:47,445 - INFO - Update id=821253903 is handled. Duration 454 ms by bot id=7597499330
2025-03-28 23:20:49,279 - INFO - Update id=821253904 is handled. Duration 140 ms by bot id=7597499330
2025-03-28 23:20:50,612 - INFO - Update id=821253905 is handled. Duration 170 ms by bot id=7597499330
2025-03-28 23:20:59,640 - INFO - Connecting to 149.154.167.51:443/TcpFull...
2025-03-28 23:20:59,763 - INFO - Connection to 149.154.167.51:443/TcpFull complete!
2025-03-28 23:21:00,658 - INFO - Update id=821253906 is handled. Duration 1031 ms by bot id=7597499330
2025-03-28 23:21:39,470 - WARNING - Server closed the connection: [WinError 64] Указанное сетевое имя более недоступно
2025-03-28 23:21:39,470 - INFO - Connection closed while receiving data: [WinError 64] Указанное сетевое имя более недоступно
2025-03-28 23:21:39,470 - INFO - Closing current connection to begin reconnect...
2025-03-28 23:21:39,470 - INFO - Connecting to 149.154.167.51:443/TcpFull...
2025-03-28 23:21:39,470 - INFO - <class 'ConnectionResetError'> during disconnect: [WinError 64] Указанное сетевое имя более недоступно
2025-03-28 23:21:39,591 - INFO - Connection to 149.154.167.51:443/TcpFull complete!
2025-03-28 23:21:45,295 - WARNING - Error executing high-level request after reconnect: <class 'sqlite3.OperationalError'>: database is locked
2025-03-28 23:21:50,808 - WARNING - Cannot get difference since the account is likely misusing the session: database is locked
2025-03-28 23:21:50,808 - INFO - Disconnecting from 149.154.167.51:443/TcpFull...
2025-03-28 23:21:50,808 - INFO - Disconnection from 149.154.167.51:443/TcpFull complete!
2025-03-28 23:21:50,809 - ERROR - Unhandled exception from keepalive_handle after cancelling <class '_asyncio.Task'> (<Task finished name='Task-14' coro=<UpdateMethods._keepalive_loop() done, defined at C:\Users\AORUS\Documents\GitHub\Bot7k\venv\lib\site-packages\telethon\client\updates.py:481> exception=OperationalError('database is locked')>)
Traceback (most recent call last):
  File "C:\Users\AORUS\Documents\GitHub\Bot7k\venv\lib\site-packages\telethon\helpers.py", line 176, in _cancel
    await task
  File "C:\Users\AORUS\Documents\GitHub\Bot7k\venv\lib\site-packages\telethon\client\updates.py", line 517, in _keepalive_loop
    self._save_states_and_entities()
  File "C:\Users\AORUS\Documents\GitHub\Bot7k\venv\lib\site-packages\telethon\client\telegrambaseclient.py", line 694, in _save_states_and_entities
    self.session.process_entities(types.contacts.ResolvedPeer(None, [e._as_input_peer() for e in entities], []))
  File "C:\Users\AORUS\Documents\GitHub\Bot7k\venv\lib\site-packages\telethon\sessions\sqlite.py", line 301, in process_entities
    c.executemany(
sqlite3.OperationalError: database is locked
2025-03-28 23:21:56,331 - ERROR - Task exception was never retrieved
future: <Task finished name='Task-576' coro=<TelegramBaseClient._disconnect_coro() done, defined at C:\Users\AORUS\Documents\GitHub\Bot7k\venv\lib\site-packages\telethon\client\telegrambaseclient.py:707> exception=OperationalError('database is locked')>
Traceback (most recent call last):
  File "C:\Users\AORUS\Documents\GitHub\Bot7k\venv\lib\site-packages\telethon\client\telegrambaseclient.py", line 737, in _disconnect_coro
    self._save_states_and_entities()
  File "C:\Users\AORUS\Documents\GitHub\Bot7k\venv\lib\site-packages\telethon\client\telegrambaseclient.py", line 694, in _save_states_and_entities
    self.session.process_entities(types.contacts.ResolvedPeer(None, [e._as_input_peer() for e in entities], []))
  File "C:\Users\AORUS\Documents\GitHub\Bot7k\venv\lib\site-packages\telethon\sessions\sqlite.py", line 301, in process_entities
    c.executemany(
sqlite3.OperationalError: database is locked
2025-03-28 23:23:40,162 - WARNING - Server closed the connection: [WinError 64] Указанное сетевое имя более недоступно
2025-03-28 23:23:40,162 - INFO - Connection closed while receiving data: [WinError 64] Указанное сетевое имя более недоступно
2025-03-28 23:23:40,162 - INFO - Closing current connection to begin reconnect...
2025-03-28 23:23:40,163 - INFO - Connecting to 149.154.167.51:443/TcpFull...
2025-03-28 23:23:40,164 - INFO - <class 'ConnectionResetError'> during disconnect: [WinError 64] Указанное сетевое имя более недоступно
2025-03-28 23:23:40,296 - INFO - Connection to 149.154.167.51:443/TcpFull complete!
2025-03-28 23:25:23,456 - WARNING - Server closed the connection: [WinError 64] Указанное сетевое имя более недоступно
2025-03-28 23:25:23,457 - INFO - Connection closed while receiving data: [WinError 64] Указанное сетевое имя более недоступно
2025-03-28 23:25:23,457 - INFO - Closing current connection to begin reconnect...
2025-03-28 23:25:23,457 - INFO - Connecting to 149.154.167.51:443/TcpFull...
2025-03-28 23:25:23,458 - INFO - <class 'ConnectionResetError'> during disconnect: [WinError 64] Указанное сетевое имя более недоступно
2025-03-28 23:25:23,591 - INFO - Connection to 149.154.167.51:443/TcpFull complete!
2025-03-28 23:25:29,259 - WARNING - Error executing high-level request after reconnect: <class 'sqlite3.OperationalError'>: database is locked
2025-03-28 23:25:34,782 - WARNING - Cannot get difference since the account is likely misusing the session: database is locked
2025-03-28 23:25:34,783 - INFO - Disconnecting from 149.154.167.51:443/TcpFull...
2025-03-28 23:25:34,783 - INFO - Disconnection from 149.154.167.51:443/TcpFull complete!
2025-03-28 23:25:34,783 - ERROR - Unhandled exception from keepalive_handle after cancelling <class '_asyncio.Task'> (<Task finished name='Task-192' coro=<UpdateMethods._keepalive_loop() done, defined at C:\Users\AORUS\Documents\GitHub\Bot7k\venv\lib\site-packages\telethon\client\updates.py:481> exception=OperationalError('database is locked')>)
Traceback (most recent call last):
  File "C:\Users\AORUS\Documents\GitHub\Bot7k\venv\lib\site-packages\telethon\helpers.py", line 176, in _cancel
    await task
  File "C:\Users\AORUS\Documents\GitHub\Bot7k\venv\lib\site-packages\telethon\client\updates.py", line 517, in _keepalive_loop
    self._save_states_and_entities()
  File "C:\Users\AORUS\Documents\GitHub\Bot7k\venv\lib\site-packages\telethon\client\telegrambaseclient.py", line 694, in _save_states_and_entities
    self.session.process_entities(types.contacts.ResolvedPeer(None, [e._as_input_peer() for e in entities], []))
  File "C:\Users\AORUS\Documents\GitHub\Bot7k\venv\lib\site-packages\telethon\sessions\sqlite.py", line 301, in process_entities
    c.executemany(
sqlite3.OperationalError: database is locked
2025-03-28 23:25:40,284 - ERROR - Task exception was never retrieved
future: <Task finished name='Task-657' coro=<TelegramBaseClient._disconnect_coro() done, defined at C:\Users\AORUS\Documents\GitHub\Bot7k\venv\lib\site-packages\telethon\client\telegrambaseclient.py:707> exception=OperationalError('database is locked')>
Traceback (most recent call last):
  File "C:\Users\AORUS\Documents\GitHub\Bot7k\venv\lib\site-packages\telethon\client\telegrambaseclient.py", line 737, in _disconnect_coro
    self._save_states_and_entities()
  File "C:\Users\AORUS\Documents\GitHub\Bot7k\venv\lib\site-packages\telethon\client\telegrambaseclient.py", line 694, in _save_states_and_entities
    self.session.process_entities(types.contacts.ResolvedPeer(None, [e._as_input_peer() for e in entities], []))
  File "C:\Users\AORUS\Documents\GitHub\Bot7k\venv\lib\site-packages\telethon\sessions\sqlite.py", line 301, in process_entities
    c.executemany(
sqlite3.OperationalError: database is locked
2025-03-28 23:26:13,527 - INFO - Polling stopped for bot @Testo1113_Bot id=7597499330 - 'Testo123'
2025-03-28 23:26:13,528 - INFO - Polling stopped
2025-03-28 23:26:13,529 - INFO - Бот остановлен пользователем
2025-03-28 23:26:13,582 - ERROR - Task exception was never retrieved
future: <Task finished name='Task-121' coro=<UpdateMethods._keepalive_loop() done, defined at C:\Users\AORUS\Documents\GitHub\Bot7k\venv\lib\site-packages\telethon\client\updates.py:481> exception=OperationalError('database is locked')>
Traceback (most recent call last):
  File "C:\Users\AORUS\Documents\GitHub\Bot7k\venv\lib\site-packages\telethon\client\updates.py", line 517, in _keepalive_loop
    self._save_states_and_entities()
  File "C:\Users\AORUS\Documents\GitHub\Bot7k\venv\lib\site-packages\telethon\client\telegrambaseclient.py", line 694, in _save_states_and_entities
    self.session.process_entities(types.contacts.ResolvedPeer(None, [e._as_input_peer() for e in entities], []))
  File "C:\Users\AORUS\Documents\GitHub\Bot7k\venv\lib\site-packages\telethon\sessions\sqlite.py", line 301, in process_entities
    c.executemany(
sqlite3.OperationalError: database is locked
2025-03-28 23:26:13,586 - ERROR - Task exception was never retrieved
future: <Task finished name='Task-244' coro=<UpdateMethods._keepalive_loop() done, defined at C:\Users\AORUS\Documents\GitHub\Bot7k\venv\lib\site-packages\telethon\client\updates.py:481> exception=OperationalError('database is locked')>
Traceback (most recent call last):
  File "C:\Users\AORUS\Documents\GitHub\Bot7k\venv\lib\site-packages\telethon\client\updates.py", line 517, in _keepalive_loop
    self._save_states_and_entities()
  File "C:\Users\AORUS\Documents\GitHub\Bot7k\venv\lib\site-packages\telethon\client\telegrambaseclient.py", line 694, in _save_states_and_entities
    self.session.process_entities(types.contacts.ResolvedPeer(None, [e._as_input_peer() for e in entities], []))
  File "C:\Users\AORUS\Documents\GitHub\Bot7k\venv\lib\site-packages\telethon\sessions\sqlite.py", line 301, in process_entities
    c.executemany(
sqlite3.OperationalError: database is locked
2025-03-28 23:26:13,589 - ERROR - Task exception was never retrieved
future: <Task finished name='Task-306' coro=<UpdateMethods._keepalive_loop() done, defined at C:\Users\AORUS\Documents\GitHub\Bot7k\venv\lib\site-packages\telethon\client\updates.py:481> exception=OperationalError('database is locked')>
Traceback (most recent call last):
  File "C:\Users\AORUS\Documents\GitHub\Bot7k\venv\lib\site-packages\telethon\client\updates.py", line 517, in _keepalive_loop
    self._save_states_and_entities()
  File "C:\Users\AORUS\Documents\GitHub\Bot7k\venv\lib\site-packages\telethon\client\telegrambaseclient.py", line 694, in _save_states_and_entities
    self.session.process_entities(types.contacts.ResolvedPeer(None, [e._as_input_peer() for e in entities], []))
  File "C:\Users\AORUS\Documents\GitHub\Bot7k\venv\lib\site-packages\telethon\sessions\sqlite.py", line 301, in process_entities
    c.executemany(
sqlite3.OperationalError: database is locked
2025-03-28 23:26:13,591 - ERROR - Task exception was never retrieved
future: <Task finished name='Task-406' coro=<UpdateMethods._keepalive_loop() done, defined at C:\Users\AORUS\Documents\GitHub\Bot7k\venv\lib\site-packages\telethon\client\updates.py:481> exception=OperationalError('database is locked')>
Traceback (most recent call last):
  File "C:\Users\AORUS\Documents\GitHub\Bot7k\venv\lib\site-packages\telethon\client\updates.py", line 517, in _keepalive_loop
    self._save_states_and_entities()
  File "C:\Users\AORUS\Documents\GitHub\Bot7k\venv\lib\site-packages\telethon\client\telegrambaseclient.py", line 694, in _save_states_and_entities
    self.session.process_entities(types.contacts.ResolvedPeer(None, [e._as_input_peer() for e in entities], []))
  File "C:\Users\AORUS\Documents\GitHub\Bot7k\venv\lib\site-packages\telethon\sessions\sqlite.py", line 301, in process_entities
    c.executemany(
sqlite3.OperationalError: database is locked
2025-03-28 23:26:13,596 - ERROR - Task exception was never retrieved
future: <Task finished name='Task-555' coro=<UpdateMethods._keepalive_loop() done, defined at C:\Users\AORUS\Documents\GitHub\Bot7k\venv\lib\site-packages\telethon\client\updates.py:481> exception=OperationalError('database is locked')>
Traceback (most recent call last):
  File "C:\Users\AORUS\Documents\GitHub\Bot7k\venv\lib\site-packages\telethon\client\updates.py", line 517, in _keepalive_loop
    self._save_states_and_entities()
  File "C:\Users\AORUS\Documents\GitHub\Bot7k\venv\lib\site-packages\telethon\client\telegrambaseclient.py", line 694, in _save_states_and_entities
    self.session.process_entities(types.contacts.ResolvedPeer(None, [e._as_input_peer() for e in entities], []))
  File "C:\Users\AORUS\Documents\GitHub\Bot7k\venv\lib\site-packages\telethon\sessions\sqlite.py", line 301, in process_entities
    c.executemany(
sqlite3.OperationalError: database is locked
2025-03-28 23:26:19,117 - INFO - Connecting to 149.154.167.51:443/TcpFull...
2025-03-28 23:26:19,244 - INFO - Connection to 149.154.167.51:443/TcpFull complete!
2025-03-28 23:26:19,794 - INFO - Start polling
2025-03-28 23:26:20,223 - INFO - Run polling for bot @Testo1113_Bot id=7597499330 - 'Testo123'
2025-03-28 23:26:23,400 - INFO - Update id=821253907 is handled. Duration 391 ms by bot id=7597499330
2025-03-28 23:26:25,282 - INFO - Update id=821253908 is handled. Duration 265 ms by bot id=7597499330
2025-03-28 23:26:32,188 - INFO - Connecting to 149.154.167.51:443/TcpFull...
2025-03-28 23:26:32,304 - INFO - Connection to 149.154.167.51:443/TcpFull complete!
2025-03-28 23:26:37,956 - INFO - Update id=821253909 is handled. Duration 5781 ms by bot id=7597499330
2025-03-28 23:26:40,933 - INFO - Update id=821253910 is handled. Duration 172 ms by bot id=7597499330
2025-03-28 23:28:02,420 - WARNING - Server closed the connection: 0 bytes read on a total of 8 expected bytes
2025-03-28 23:28:02,421 - INFO - Connection closed while receiving data: 0 bytes read on a total of 8 expected bytes
2025-03-28 23:28:02,421 - INFO - Closing current connection to begin reconnect...
2025-03-28 23:28:02,421 - INFO - Connecting to 149.154.167.51:443/TcpFull...
2025-03-28 23:28:02,537 - INFO - Connection to 149.154.167.51:443/TcpFull complete!
2025-03-28 23:29:26,174 - ERROR - Task was destroyed but it is pending!
task: <Task pending name='Task-64' coro=<Connection._send_loop() done, defined at C:\Users\AORUS\Documents\GitHub\Bot7k\venv\lib\site-packages\telethon\network\connection\connection.py:316> wait_for=<Future cancelled>>
2025-03-28 23:29:26,176 - ERROR - Task was destroyed but it is pending!
task: <Task pending name='Task-65' coro=<Connection._recv_loop() running at C:\Users\AORUS\Documents\GitHub\Bot7k\venv\lib\site-packages\telethon\network\connection\connection.py:361> wait_for=<Future pending cb=[Task.task_wakeup()]>>
2025-03-28 23:29:26,176 - ERROR - Task was destroyed but it is pending!
task: <Task pending name='Task-66' coro=<MTProtoSender._send_loop() done, defined at C:\Users\AORUS\Documents\GitHub\Bot7k\venv\lib\site-packages\telethon\network\mtprotosender.py:446> wait_for=<Future pending cb=[Task.task_wakeup()]>>
2025-03-28 23:29:26,176 - ERROR - Task was destroyed but it is pending!
task: <Task pending name='Task-67' coro=<MTProtoSender._recv_loop() done, defined at C:\Users\AORUS\Documents\GitHub\Bot7k\venv\lib\site-packages\telethon\network\mtprotosender.py:497> wait_for=<Future cancelled>>
2025-03-28 23:35:25,466 - INFO - Polling stopped
2025-03-28 23:35:25,467 - INFO - Polling stopped for bot @Testo1113_Bot id=7597499330 - 'Testo123'
2025-03-28 23:35:25,468 - INFO - Бот остановлен пользователем
2025-03-28 23:35:25,507 - ERROR - Task exception was never retrieved
future: <Task finished name='Task-14' coro=<UpdateMethods._keepalive_loop() done, defined at C:\Users\AORUS\Documents\GitHub\Bot7k\venv\lib\site-packages\telethon\client\updates.py:481> exception=OperationalError('database is locked')>
Traceback (most recent call last):
  File "C:\Users\AORUS\Documents\GitHub\Bot7k\venv\lib\site-packages\telethon\client\updates.py", line 517, in _keepalive_loop
    self._save_states_and_entities()
  File "C:\Users\AORUS\Documents\GitHub\Bot7k\venv\lib\site-packages\telethon\client\telegrambaseclient.py", line 694, in _save_states_and_entities
    self.session.process_entities(types.contacts.ResolvedPeer(None, [e._as_input_peer() for e in entities], []))
  File "C:\Users\AORUS\Documents\GitHub\Bot7k\venv\lib\site-packages\telethon\sessions\sqlite.py", line 301, in process_entities
    c.executemany(
sqlite3.OperationalError: database is locked
2025-03-28 23:35:27,879 - INFO - Connecting to 149.154.167.51:443/TcpFull...
2025-03-28 23:35:28,006 - INFO - Connection to 149.154.167.51:443/TcpFull complete!
2025-03-28 23:35:28,774 - INFO - Start polling
2025-03-28 23:35:29,181 - INFO - Run polling for bot @Testo1113_Bot id=7597499330 - 'Testo123'
2025-03-28 23:35:31,327 - INFO - Update id=821253911 is handled. Duration 483 ms by bot id=7597499330
2025-03-28 23:35:37,179 - INFO - Connecting to 149.154.167.51:443/TcpFull...
2025-03-28 23:35:37,306 - INFO - Connection to 149.154.167.51:443/TcpFull complete!
2025-03-28 23:35:42,979 - INFO - Update id=821253912 is handled. Duration 5797 ms by bot id=7597499330
2025-03-28 23:35:46,947 - INFO - Update id=821253913 is handled. Duration 157 ms by bot id=7597499330
2025-03-28 23:35:49,000 - ERROR - Task was destroyed but it is pending!
task: <Task pending name='Task-30' coro=<Connection._send_loop() done, defined at C:\Users\AORUS\Documents\GitHub\Bot7k\venv\lib\site-packages\telethon\network\connection\connection.py:316> wait_for=<Future cancelled>>
2025-03-28 23:35:49,011 - ERROR - Task was destroyed but it is pending!
task: <Task pending name='Task-31' coro=<Connection._recv_loop() running at C:\Users\AORUS\Documents\GitHub\Bot7k\venv\lib\site-packages\telethon\network\connection\connection.py:361> wait_for=<Future pending cb=[Task.task_wakeup()]>>
2025-03-28 23:35:49,011 - ERROR - Task was destroyed but it is pending!
task: <Task pending name='Task-32' coro=<MTProtoSender._send_loop() done, defined at C:\Users\AORUS\Documents\GitHub\Bot7k\venv\lib\site-packages\telethon\network\mtprotosender.py:446> wait_for=<Future pending cb=[Task.task_wakeup()]>>
2025-03-28 23:35:49,012 - ERROR - Task was destroyed but it is pending!
task: <Task pending name='Task-33' coro=<MTProtoSender._recv_loop() done, defined at C:\Users\AORUS\Documents\GitHub\Bot7k\venv\lib\site-packages\telethon\network\mtprotosender.py:497> wait_for=<Future cancelled>>
2025-03-28 23:35:49,233 - INFO - Update id=821253914 is handled. Duration 233 ms by bot id=7597499330
2025-03-28 23:36:20,022 - INFO - Connecting to 149.154.167.51:443/TcpFull...
2025-03-28 23:36:20,148 - INFO - Connection to 149.154.167.51:443/TcpFull complete!
2025-03-28 23:36:26,083 - INFO - Update id=821253915 is handled. Duration 6062 ms by bot id=7597499330
2025-03-28 23:36:48,885 - INFO - Update id=821253916 is not handled. Duration 0 ms by bot id=7597499330
2025-03-28 23:36:54,083 - INFO - Update id=821253917 is handled. Duration 453 ms by bot id=7597499330
2025-03-28 23:37:11,341 - INFO - Connecting to 149.154.167.51:443/TcpFull...
2025-03-28 23:37:11,463 - INFO - Connection to 149.154.167.51:443/TcpFull complete!
2025-03-28 23:37:12,226 - ERROR - Task was destroyed but it is pending!
task: <Task pending name='Task-51' coro=<Connection._send_loop() done, defined at C:\Users\AORUS\Documents\GitHub\Bot7k\venv\lib\site-packages\telethon\network\connection\connection.py:316> wait_for=<Future cancelled>>
2025-03-28 23:37:12,265 - ERROR - Task was destroyed but it is pending!
task: <Task pending name='Task-52' coro=<Connection._recv_loop() running at C:\Users\AORUS\Documents\GitHub\Bot7k\venv\lib\site-packages\telethon\network\connection\connection.py:361> wait_for=<Future pending cb=[Task.task_wakeup()]>>
2025-03-28 23:37:12,265 - ERROR - Task was destroyed but it is pending!
task: <Task pending name='Task-53' coro=<MTProtoSender._send_loop() done, defined at C:\Users\AORUS\Documents\GitHub\Bot7k\venv\lib\site-packages\telethon\network\mtprotosender.py:446> wait_for=<Future pending cb=[Task.task_wakeup()]>>
2025-03-28 23:37:12,265 - ERROR - Task was destroyed but it is pending!
task: <Task pending name='Task-54' coro=<MTProtoSender._recv_loop() done, defined at C:\Users\AORUS\Documents\GitHub\Bot7k\venv\lib\site-packages\telethon\network\mtprotosender.py:497> wait_for=<Future cancelled>>
2025-03-28 23:37:12,720 - INFO - Update id=821253918 is handled. Duration 1391 ms by bot id=7597499330
